2025-10-20 23:29:12,557 - database.db - INFO - Database initialized successfully
2025-10-20 23:29:13,610 - aiogram - INFO - Bot: nizomjons_bot [@nizomjons_bot]
2025-10-20 23:29:14,019 - aiogram - WARNING - Updates were skipped successfully.
2025-10-20 23:29:14,019 - __main__ - INFO - üöÄ Bot is starting...
2025-10-20 23:29:14,224 - __main__ - INFO - Bot name: nizomjons_bot
2025-10-20 23:29:14,236 - __main__ - INFO - ‚úÖ All handlers registered successfully
2025-10-20 23:29:14,237 - __main__ - INFO - ‚úÖ Bot started successfully!
2025-10-20 23:29:14,237 - aiogram.dispatcher.dispatcher - INFO - Start polling.
2025-10-20 23:29:24,257 - database.db - ERROR - Error saving user: table users has 5 columns but 6 values were supplied
2025-10-20 23:33:50,246 - database.db - ERROR - Error creating application: table applications has no column named username
2025-10-20 23:35:30,654 - database.db - ERROR - Error saving user: table users has 5 columns but 6 values were supplied
2025-10-20 23:41:43,991 - __main__ - INFO - ‚è∏ Bot is shutting down...
2025-10-20 23:41:43,992 - __main__ - INFO - ‚úÖ Bot stopped
2025-10-20 23:41:43,992 - aiogram.dispatcher.dispatcher - INFO - Stop polling...
2025-10-20 23:41:43,992 - aiogram - WARNING - Goodbye!
2025-10-20 23:41:46,424 - database.db - INFO - Database initialized successfully
2025-10-20 23:41:47,698 - aiogram - INFO - Bot: nizomjons_bot [@nizomjons_bot]
2025-10-20 23:41:48,108 - aiogram - WARNING - Updates were skipped successfully.
2025-10-20 23:41:48,108 - __main__ - INFO - üöÄ Bot is starting...
2025-10-20 23:41:48,312 - __main__ - INFO - Bot name: nizomjons_bot
2025-10-20 23:41:48,323 - __main__ - INFO - ‚úÖ All handlers registered successfully
2025-10-20 23:41:48,323 - __main__ - INFO - ‚úÖ Bot started successfully!
2025-10-20 23:41:48,323 - aiogram.dispatcher.dispatcher - INFO - Start polling.
2025-10-20 23:41:53,980 - database.db - ERROR - Error saving user: table users has 5 columns but 6 values were supplied
2025-10-20 23:56:03,828 - __main__ - INFO - ‚è∏ Bot is shutting down...
2025-10-20 23:56:03,846 - __main__ - INFO - ‚úÖ Bot stopped
2025-10-20 23:56:03,846 - aiogram.dispatcher.dispatcher - INFO - Stop polling...
2025-10-20 23:56:03,847 - aiogram - WARNING - Goodbye!
2025-10-20 23:56:37,809 - database.db - INFO - Database initialized successfully
2025-10-20 23:56:38,785 - aiogram - INFO - Bot: nizomjons_bot [@nizomjons_bot]
2025-10-20 23:56:39,195 - aiogram - WARNING - Updates were skipped successfully.
2025-10-20 23:56:39,195 - __main__ - INFO - üöÄ Bot is starting...
2025-10-20 23:56:39,400 - __main__ - INFO - Bot name: nizomjons_bot
2025-10-20 23:56:39,412 - __main__ - INFO - ‚úÖ All handlers registered successfully
2025-10-20 23:56:39,412 - __main__ - INFO - ‚úÖ Bot started successfully!
2025-10-20 23:56:39,412 - aiogram.dispatcher.dispatcher - INFO - Start polling.
2025-10-20 23:56:45,545 - database.db - ERROR - Error saving user: table users has 5 columns but 6 values were supplied
2025-10-20 23:59:27,391 - __main__ - INFO - ‚è∏ Bot is shutting down...
2025-10-20 23:59:27,391 - __main__ - INFO - ‚úÖ Bot stopped
2025-10-20 23:59:27,391 - aiogram.dispatcher.dispatcher - INFO - Stop polling...
2025-10-20 23:59:27,396 - aiogram - WARNING - Goodbye!
2025-10-21 00:08:47,984 - database.db - INFO - Database initialized successfully
2025-10-21 00:08:49,106 - aiogram - INFO - Bot: nizomjons_bot [@nizomjons_bot]
2025-10-21 00:08:49,515 - aiogram - WARNING - Updates were skipped successfully.
2025-10-21 00:08:49,516 - __main__ - INFO - üöÄ Bot is starting...
2025-10-21 00:08:49,720 - __main__ - INFO - Bot name: nizomjons_bot
2025-10-21 00:08:49,731 - __main__ - INFO - ‚úÖ All handlers registered successfully
2025-10-21 00:08:49,731 - __main__ - INFO - ‚úÖ Bot started successfully!
2025-10-21 00:08:49,732 - aiogram.dispatcher.dispatcher - INFO - Start polling.
2025-10-21 00:09:01,808 - database.db - ERROR - Error saving user: table users has 5 columns but 6 values were supplied
2025-10-21 00:13:04,664 - __main__ - INFO - ‚è∏ Bot is shutting down...
2025-10-21 00:13:04,665 - __main__ - INFO - ‚úÖ Bot stopped
2025-10-21 00:13:04,665 - aiogram.dispatcher.dispatcher - INFO - Stop polling...
2025-10-21 00:13:04,666 - aiogram - WARNING - Goodbye!
2025-10-21 00:13:06,330 - database.db - INFO - Database initialized successfully
2025-10-21 00:13:07,155 - aiogram - INFO - Bot: nizomjons_bot [@nizomjons_bot]
2025-10-21 00:13:07,565 - aiogram - WARNING - Updates were skipped successfully.
2025-10-21 00:13:07,565 - __main__ - INFO - üöÄ Bot is starting...
2025-10-21 00:13:07,769 - __main__ - INFO - Bot name: nizomjons_bot
2025-10-21 00:13:07,782 - __main__ - INFO - ‚úÖ All handlers registered successfully
2025-10-21 00:13:07,782 - __main__ - INFO - ‚úÖ Bot started successfully!
2025-10-21 00:13:07,782 - aiogram.dispatcher.dispatcher - INFO - Start polling.
2025-10-21 00:13:10,845 - database.db - ERROR - Error saving user: table users has 5 columns but 6 values were supplied
2025-10-21 00:23:26,247 - __main__ - INFO - ‚è∏ Bot is shutting down...
2025-10-21 00:23:26,247 - __main__ - INFO - ‚úÖ Bot stopped
2025-10-21 00:23:26,248 - aiogram.dispatcher.dispatcher - INFO - Stop polling...
2025-10-21 00:23:26,248 - aiogram - WARNING - Goodbye!
2025-10-21 00:23:28,152 - database.db - INFO - Database initialized successfully
2025-10-21 00:23:29,139 - aiogram - INFO - Bot: nizomjons_bot [@nizomjons_bot]
2025-10-21 00:23:29,543 - aiogram - WARNING - Updates were skipped successfully.
2025-10-21 00:23:29,543 - __main__ - INFO - üöÄ Bot is starting...
2025-10-21 00:23:29,748 - __main__ - INFO - Bot name: nizomjons_bot
2025-10-21 00:23:29,761 - __main__ - INFO - ‚úÖ All handlers registered successfully
2025-10-21 00:23:29,762 - __main__ - INFO - ‚úÖ Bot started successfully!
2025-10-21 00:23:29,762 - aiogram.dispatcher.dispatcher - INFO - Start polling.
2025-10-21 00:23:44,146 - database.db - ERROR - Error saving user: table users has 5 columns but 6 values were supplied
2025-10-21 00:24:09,349 - __main__ - INFO - ‚è∏ Bot is shutting down...
2025-10-21 00:24:09,350 - __main__ - INFO - ‚úÖ Bot stopped
2025-10-21 00:24:09,350 - aiogram.dispatcher.dispatcher - INFO - Stop polling...
2025-10-21 00:24:09,351 - aiogram - WARNING - Goodbye!
2025-10-21 00:24:10,852 - database.db - INFO - Database initialized successfully
2025-10-21 00:24:11,733 - aiogram - INFO - Bot: nizomjons_bot [@nizomjons_bot]
2025-10-21 00:24:12,142 - aiogram - WARNING - Updates were skipped successfully.
2025-10-21 00:24:12,142 - __main__ - INFO - üöÄ Bot is starting...
2025-10-21 00:24:12,348 - __main__ - INFO - Bot name: nizomjons_bot
2025-10-21 00:24:12,360 - __main__ - INFO - ‚úÖ All handlers registered successfully
2025-10-21 00:24:12,360 - __main__ - INFO - ‚úÖ Bot started successfully!
2025-10-21 00:24:12,360 - aiogram.dispatcher.dispatcher - INFO - Start polling.
2025-10-21 00:24:15,832 - database.db - ERROR - Error saving user: table users has 5 columns but 6 values were supplied
2025-10-21 00:26:02,570 - __main__ - INFO - ‚è∏ Bot is shutting down...
2025-10-21 00:26:02,570 - __main__ - INFO - ‚úÖ Bot stopped
2025-10-21 00:26:02,570 - aiogram.dispatcher.dispatcher - INFO - Stop polling...
2025-10-21 00:26:02,575 - aiogram - WARNING - Goodbye!
2025-10-21 00:26:04,316 - database.db - INFO - Database initialized successfully
2025-10-21 00:26:05,193 - aiogram - INFO - Bot: nizomjons_bot [@nizomjons_bot]
2025-10-21 00:26:05,606 - aiogram - WARNING - Updates were skipped successfully.
2025-10-21 00:26:05,606 - __main__ - INFO - üöÄ Bot is starting...
2025-10-21 00:26:05,811 - __main__ - INFO - Bot name: nizomjons_bot
2025-10-21 00:26:05,823 - __main__ - INFO - ‚úÖ All handlers registered successfully
2025-10-21 00:26:05,823 - __main__ - INFO - ‚úÖ Bot started successfully!
2025-10-21 00:26:05,823 - aiogram.dispatcher.dispatcher - INFO - Start polling.
2025-10-21 00:28:06,266 - __main__ - INFO - ‚è∏ Bot is shutting down...
2025-10-21 00:28:06,267 - __main__ - INFO - ‚úÖ Bot stopped
2025-10-21 00:28:06,267 - aiogram.dispatcher.dispatcher - INFO - Stop polling...
2025-10-21 00:28:06,267 - aiogram - WARNING - Goodbye!
2025-10-21 00:28:07,735 - database.db - INFO - Database initialized successfully
2025-10-21 00:28:08,486 - aiogram - INFO - Bot: nizomjons_bot [@nizomjons_bot]
2025-10-21 00:28:08,891 - aiogram - WARNING - Updates were skipped successfully.
2025-10-21 00:28:08,892 - __main__ - INFO - üöÄ Bot is starting...
2025-10-21 00:28:09,096 - __main__ - INFO - Bot name: nizomjons_bot
2025-10-21 00:28:09,107 - __main__ - INFO - ‚úÖ All handlers registered successfully
2025-10-21 00:28:09,107 - __main__ - INFO - ‚úÖ Bot started successfully!
2025-10-21 00:28:09,108 - aiogram.dispatcher.dispatcher - INFO - Start polling.
2025-10-21 00:43:27,240 - aiogram.dispatcher.dispatcher - ERROR - Cause exception while getting updates.
Traceback (most recent call last):
  File "/home/nizomjon/PycharmProjects/Tiu_bot/.venv/lib/python3.9/site-packages/aiogram/dispatcher/dispatcher.py", line 381, in start_polling
    updates = await self.bot.get_updates(
  File "/home/nizomjon/PycharmProjects/Tiu_bot/.venv/lib/python3.9/site-packages/aiogram/bot/bot.py", line 110, in get_updates
    result = await self.request(api.Methods.GET_UPDATES, payload)
  File "/home/nizomjon/PycharmProjects/Tiu_bot/.venv/lib/python3.9/site-packages/aiogram/bot/base.py", line 236, in request
    return await api.make_request(await self.get_session(), self.server, self.__token, method, data, files,
  File "/home/nizomjon/PycharmProjects/Tiu_bot/.venv/lib/python3.9/site-packages/aiogram/bot/api.py", line 139, in make_request
    async with session.post(url, data=req, **kwargs) as response:
  File "/home/nizomjon/PycharmProjects/Tiu_bot/.venv/lib/python3.9/site-packages/aiohttp/client.py", line 1167, in __aenter__
    self._resp = await self._coro
  File "/home/nizomjon/PycharmProjects/Tiu_bot/.venv/lib/python3.9/site-packages/aiohttp/client.py", line 586, in _request
    await resp.start(conn)
  File "/home/nizomjon/PycharmProjects/Tiu_bot/.venv/lib/python3.9/site-packages/aiohttp/client_reqrep.py", line 920, in start
    self._continue = None
  File "/home/nizomjon/PycharmProjects/Tiu_bot/.venv/lib/python3.9/site-packages/aiohttp/helpers.py", line 725, in __exit__
    raise asyncio.TimeoutError from None
asyncio.exceptions.TimeoutError
2025-10-21 00:56:29,239 - aiogram.dispatcher.dispatcher - ERROR - Cause exception while getting updates.
Traceback (most recent call last):
  File "/home/nizomjon/PycharmProjects/Tiu_bot/.venv/lib/python3.9/site-packages/aiogram/dispatcher/dispatcher.py", line 381, in start_polling
    updates = await self.bot.get_updates(
  File "/home/nizomjon/PycharmProjects/Tiu_bot/.venv/lib/python3.9/site-packages/aiogram/bot/bot.py", line 110, in get_updates
    result = await self.request(api.Methods.GET_UPDATES, payload)
  File "/home/nizomjon/PycharmProjects/Tiu_bot/.venv/lib/python3.9/site-packages/aiogram/bot/base.py", line 236, in request
    return await api.make_request(await self.get_session(), self.server, self.__token, method, data, files,
  File "/home/nizomjon/PycharmProjects/Tiu_bot/.venv/lib/python3.9/site-packages/aiogram/bot/api.py", line 139, in make_request
    async with session.post(url, data=req, **kwargs) as response:
  File "/home/nizomjon/PycharmProjects/Tiu_bot/.venv/lib/python3.9/site-packages/aiohttp/client.py", line 1167, in __aenter__
    self._resp = await self._coro
  File "/home/nizomjon/PycharmProjects/Tiu_bot/.venv/lib/python3.9/site-packages/aiohttp/client.py", line 586, in _request
    await resp.start(conn)
  File "/home/nizomjon/PycharmProjects/Tiu_bot/.venv/lib/python3.9/site-packages/aiohttp/client_reqrep.py", line 920, in start
    self._continue = None
  File "/home/nizomjon/PycharmProjects/Tiu_bot/.venv/lib/python3.9/site-packages/aiohttp/helpers.py", line 725, in __exit__
    raise asyncio.TimeoutError from None
asyncio.exceptions.TimeoutError
2025-10-21 00:56:34,244 - aiogram.dispatcher.dispatcher - ERROR - Cause exception while getting updates.
Traceback (most recent call last):
  File "/home/nizomjon/PycharmProjects/Tiu_bot/.venv/lib/python3.9/site-packages/aiohttp/connector.py", line 1155, in _create_direct_connection
    hosts = await asyncio.shield(host_resolved)
  File "/home/nizomjon/PycharmProjects/Tiu_bot/.venv/lib/python3.9/site-packages/aiohttp/connector.py", line 874, in _resolve_host
    addrs = await self._resolver.resolve(host, port, family=self._family)
  File "/home/nizomjon/PycharmProjects/Tiu_bot/.venv/lib/python3.9/site-packages/aiohttp/resolver.py", line 33, in resolve
    infos = await self._loop.getaddrinfo(
  File "/usr/local/lib/python3.9/asyncio/base_events.py", line 856, in getaddrinfo
    return await self.run_in_executor(
  File "/usr/local/lib/python3.9/concurrent/futures/thread.py", line 58, in run
    result = self.fn(*self.args, **self.kwargs)
  File "/usr/local/lib/python3.9/socket.py", line 954, in getaddrinfo
    for res in _socket.getaddrinfo(host, port, family, type, proto, flags):
socket.gaierror: [Errno -3] Temporary failure in name resolution

The above exception was the direct cause of the following exception:

Traceback (most recent call last):
  File "/home/nizomjon/PycharmProjects/Tiu_bot/.venv/lib/python3.9/site-packages/aiogram/bot/api.py", line 139, in make_request
    async with session.post(url, data=req, **kwargs) as response:
  File "/home/nizomjon/PycharmProjects/Tiu_bot/.venv/lib/python3.9/site-packages/aiohttp/client.py", line 1167, in __aenter__
    self._resp = await self._coro
  File "/home/nizomjon/PycharmProjects/Tiu_bot/.venv/lib/python3.9/site-packages/aiohttp/client.py", line 562, in _request
    conn = await self._connector.connect(
  File "/home/nizomjon/PycharmProjects/Tiu_bot/.venv/lib/python3.9/site-packages/aiohttp/connector.py", line 540, in connect
    proto = await self._create_connection(req, traces, timeout)
  File "/home/nizomjon/PycharmProjects/Tiu_bot/.venv/lib/python3.9/site-packages/aiohttp/connector.py", line 901, in _create_connection
    _, proto = await self._create_direct_connection(req, traces, timeout)
  File "/home/nizomjon/PycharmProjects/Tiu_bot/.venv/lib/python3.9/site-packages/aiohttp/connector.py", line 1169, in _create_direct_connection
    raise ClientConnectorError(req.connection_key, exc) from exc
aiohttp.client_exceptions.ClientConnectorError: Cannot connect to host api.telegram.org:443 ssl:default [Temporary failure in name resolution]

During handling of the above exception, another exception occurred:

Traceback (most recent call last):
  File "/home/nizomjon/PycharmProjects/Tiu_bot/.venv/lib/python3.9/site-packages/aiogram/dispatcher/dispatcher.py", line 381, in start_polling
    updates = await self.bot.get_updates(
  File "/home/nizomjon/PycharmProjects/Tiu_bot/.venv/lib/python3.9/site-packages/aiogram/bot/bot.py", line 110, in get_updates
    result = await self.request(api.Methods.GET_UPDATES, payload)
  File "/home/nizomjon/PycharmProjects/Tiu_bot/.venv/lib/python3.9/site-packages/aiogram/bot/base.py", line 236, in request
    return await api.make_request(await self.get_session(), self.server, self.__token, method, data, files,
  File "/home/nizomjon/PycharmProjects/Tiu_bot/.venv/lib/python3.9/site-packages/aiogram/bot/api.py", line 142, in make_request
    raise exceptions.NetworkError(f"aiohttp client throws an error: {e.__class__.__name__}: {e}")
aiogram.utils.exceptions.NetworkError: Aiohttp client throws an error: ClientConnectorError: Cannot connect to host api.telegram.org:443 ssl:default [Temporary failure in name resolution]
2025-10-21 00:56:39,256 - aiogram.dispatcher.dispatcher - ERROR - Cause exception while getting updates.
Traceback (most recent call last):
  File "/home/nizomjon/PycharmProjects/Tiu_bot/.venv/lib/python3.9/site-packages/aiohttp/connector.py", line 1155, in _create_direct_connection
    hosts = await asyncio.shield(host_resolved)
  File "/home/nizomjon/PycharmProjects/Tiu_bot/.venv/lib/python3.9/site-packages/aiohttp/connector.py", line 874, in _resolve_host
    addrs = await self._resolver.resolve(host, port, family=self._family)
  File "/home/nizomjon/PycharmProjects/Tiu_bot/.venv/lib/python3.9/site-packages/aiohttp/resolver.py", line 33, in resolve
    infos = await self._loop.getaddrinfo(
  File "/usr/local/lib/python3.9/asyncio/base_events.py", line 856, in getaddrinfo
    return await self.run_in_executor(
  File "/usr/local/lib/python3.9/concurrent/futures/thread.py", line 58, in run
    result = self.fn(*self.args, **self.kwargs)
  File "/usr/local/lib/python3.9/socket.py", line 954, in getaddrinfo
    for res in _socket.getaddrinfo(host, port, family, type, proto, flags):
socket.gaierror: [Errno -3] Temporary failure in name resolution

The above exception was the direct cause of the following exception:

Traceback (most recent call last):
  File "/home/nizomjon/PycharmProjects/Tiu_bot/.venv/lib/python3.9/site-packages/aiogram/bot/api.py", line 139, in make_request
    async with session.post(url, data=req, **kwargs) as response:
  File "/home/nizomjon/PycharmProjects/Tiu_bot/.venv/lib/python3.9/site-packages/aiohttp/client.py", line 1167, in __aenter__
    self._resp = await self._coro
  File "/home/nizomjon/PycharmProjects/Tiu_bot/.venv/lib/python3.9/site-packages/aiohttp/client.py", line 562, in _request
    conn = await self._connector.connect(
  File "/home/nizomjon/PycharmProjects/Tiu_bot/.venv/lib/python3.9/site-packages/aiohttp/connector.py", line 540, in connect
    proto = await self._create_connection(req, traces, timeout)
  File "/home/nizomjon/PycharmProjects/Tiu_bot/.venv/lib/python3.9/site-packages/aiohttp/connector.py", line 901, in _create_connection
    _, proto = await self._create_direct_connection(req, traces, timeout)
  File "/home/nizomjon/PycharmProjects/Tiu_bot/.venv/lib/python3.9/site-packages/aiohttp/connector.py", line 1169, in _create_direct_connection
    raise ClientConnectorError(req.connection_key, exc) from exc
aiohttp.client_exceptions.ClientConnectorError: Cannot connect to host api.telegram.org:443 ssl:default [Temporary failure in name resolution]

During handling of the above exception, another exception occurred:

Traceback (most recent call last):
  File "/home/nizomjon/PycharmProjects/Tiu_bot/.venv/lib/python3.9/site-packages/aiogram/dispatcher/dispatcher.py", line 381, in start_polling
    updates = await self.bot.get_updates(
  File "/home/nizomjon/PycharmProjects/Tiu_bot/.venv/lib/python3.9/site-packages/aiogram/bot/bot.py", line 110, in get_updates
    result = await self.request(api.Methods.GET_UPDATES, payload)
  File "/home/nizomjon/PycharmProjects/Tiu_bot/.venv/lib/python3.9/site-packages/aiogram/bot/base.py", line 236, in request
    return await api.make_request(await self.get_session(), self.server, self.__token, method, data, files,
  File "/home/nizomjon/PycharmProjects/Tiu_bot/.venv/lib/python3.9/site-packages/aiogram/bot/api.py", line 142, in make_request
    raise exceptions.NetworkError(f"aiohttp client throws an error: {e.__class__.__name__}: {e}")
aiogram.utils.exceptions.NetworkError: Aiohttp client throws an error: ClientConnectorError: Cannot connect to host api.telegram.org:443 ssl:default [Temporary failure in name resolution]
2025-10-21 00:56:44,260 - aiogram.dispatcher.dispatcher - ERROR - Cause exception while getting updates.
Traceback (most recent call last):
  File "/home/nizomjon/PycharmProjects/Tiu_bot/.venv/lib/python3.9/site-packages/aiohttp/connector.py", line 1155, in _create_direct_connection
    hosts = await asyncio.shield(host_resolved)
  File "/home/nizomjon/PycharmProjects/Tiu_bot/.venv/lib/python3.9/site-packages/aiohttp/connector.py", line 874, in _resolve_host
    addrs = await self._resolver.resolve(host, port, family=self._family)
  File "/home/nizomjon/PycharmProjects/Tiu_bot/.venv/lib/python3.9/site-packages/aiohttp/resolver.py", line 33, in resolve
    infos = await self._loop.getaddrinfo(
  File "/usr/local/lib/python3.9/asyncio/base_events.py", line 856, in getaddrinfo
    return await self.run_in_executor(
  File "/usr/local/lib/python3.9/concurrent/futures/thread.py", line 58, in run
    result = self.fn(*self.args, **self.kwargs)
  File "/usr/local/lib/python3.9/socket.py", line 954, in getaddrinfo
    for res in _socket.getaddrinfo(host, port, family, type, proto, flags):
socket.gaierror: [Errno -3] Temporary failure in name resolution

The above exception was the direct cause of the following exception:

Traceback (most recent call last):
  File "/home/nizomjon/PycharmProjects/Tiu_bot/.venv/lib/python3.9/site-packages/aiogram/bot/api.py", line 139, in make_request
    async with session.post(url, data=req, **kwargs) as response:
  File "/home/nizomjon/PycharmProjects/Tiu_bot/.venv/lib/python3.9/site-packages/aiohttp/client.py", line 1167, in __aenter__
    self._resp = await self._coro
  File "/home/nizomjon/PycharmProjects/Tiu_bot/.venv/lib/python3.9/site-packages/aiohttp/client.py", line 562, in _request
    conn = await self._connector.connect(
  File "/home/nizomjon/PycharmProjects/Tiu_bot/.venv/lib/python3.9/site-packages/aiohttp/connector.py", line 540, in connect
    proto = await self._create_connection(req, traces, timeout)
  File "/home/nizomjon/PycharmProjects/Tiu_bot/.venv/lib/python3.9/site-packages/aiohttp/connector.py", line 901, in _create_connection
    _, proto = await self._create_direct_connection(req, traces, timeout)
  File "/home/nizomjon/PycharmProjects/Tiu_bot/.venv/lib/python3.9/site-packages/aiohttp/connector.py", line 1169, in _create_direct_connection
    raise ClientConnectorError(req.connection_key, exc) from exc
aiohttp.client_exceptions.ClientConnectorError: Cannot connect to host api.telegram.org:443 ssl:default [Temporary failure in name resolution]

During handling of the above exception, another exception occurred:

Traceback (most recent call last):
  File "/home/nizomjon/PycharmProjects/Tiu_bot/.venv/lib/python3.9/site-packages/aiogram/dispatcher/dispatcher.py", line 381, in start_polling
    updates = await self.bot.get_updates(
  File "/home/nizomjon/PycharmProjects/Tiu_bot/.venv/lib/python3.9/site-packages/aiogram/bot/bot.py", line 110, in get_updates
    result = await self.request(api.Methods.GET_UPDATES, payload)
  File "/home/nizomjon/PycharmProjects/Tiu_bot/.venv/lib/python3.9/site-packages/aiogram/bot/base.py", line 236, in request
    return await api.make_request(await self.get_session(), self.server, self.__token, method, data, files,
  File "/home/nizomjon/PycharmProjects/Tiu_bot/.venv/lib/python3.9/site-packages/aiogram/bot/api.py", line 142, in make_request
    raise exceptions.NetworkError(f"aiohttp client throws an error: {e.__class__.__name__}: {e}")
aiogram.utils.exceptions.NetworkError: Aiohttp client throws an error: ClientConnectorError: Cannot connect to host api.telegram.org:443 ssl:default [Temporary failure in name resolution]
2025-10-21 00:56:49,264 - aiogram.dispatcher.dispatcher - ERROR - Cause exception while getting updates.
Traceback (most recent call last):
  File "/home/nizomjon/PycharmProjects/Tiu_bot/.venv/lib/python3.9/site-packages/aiohttp/connector.py", line 1155, in _create_direct_connection
    hosts = await asyncio.shield(host_resolved)
  File "/home/nizomjon/PycharmProjects/Tiu_bot/.venv/lib/python3.9/site-packages/aiohttp/connector.py", line 874, in _resolve_host
    addrs = await self._resolver.resolve(host, port, family=self._family)
  File "/home/nizomjon/PycharmProjects/Tiu_bot/.venv/lib/python3.9/site-packages/aiohttp/resolver.py", line 33, in resolve
    infos = await self._loop.getaddrinfo(
  File "/usr/local/lib/python3.9/asyncio/base_events.py", line 856, in getaddrinfo
    return await self.run_in_executor(
  File "/usr/local/lib/python3.9/concurrent/futures/thread.py", line 58, in run
    result = self.fn(*self.args, **self.kwargs)
  File "/usr/local/lib/python3.9/socket.py", line 954, in getaddrinfo
    for res in _socket.getaddrinfo(host, port, family, type, proto, flags):
socket.gaierror: [Errno -3] Temporary failure in name resolution

The above exception was the direct cause of the following exception:

Traceback (most recent call last):
  File "/home/nizomjon/PycharmProjects/Tiu_bot/.venv/lib/python3.9/site-packages/aiogram/bot/api.py", line 139, in make_request
    async with session.post(url, data=req, **kwargs) as response:
  File "/home/nizomjon/PycharmProjects/Tiu_bot/.venv/lib/python3.9/site-packages/aiohttp/client.py", line 1167, in __aenter__
    self._resp = await self._coro
  File "/home/nizomjon/PycharmProjects/Tiu_bot/.venv/lib/python3.9/site-packages/aiohttp/client.py", line 562, in _request
    conn = await self._connector.connect(
  File "/home/nizomjon/PycharmProjects/Tiu_bot/.venv/lib/python3.9/site-packages/aiohttp/connector.py", line 540, in connect
    proto = await self._create_connection(req, traces, timeout)
  File "/home/nizomjon/PycharmProjects/Tiu_bot/.venv/lib/python3.9/site-packages/aiohttp/connector.py", line 901, in _create_connection
    _, proto = await self._create_direct_connection(req, traces, timeout)
  File "/home/nizomjon/PycharmProjects/Tiu_bot/.venv/lib/python3.9/site-packages/aiohttp/connector.py", line 1169, in _create_direct_connection
    raise ClientConnectorError(req.connection_key, exc) from exc
aiohttp.client_exceptions.ClientConnectorError: Cannot connect to host api.telegram.org:443 ssl:default [Temporary failure in name resolution]

During handling of the above exception, another exception occurred:

Traceback (most recent call last):
  File "/home/nizomjon/PycharmProjects/Tiu_bot/.venv/lib/python3.9/site-packages/aiogram/dispatcher/dispatcher.py", line 381, in start_polling
    updates = await self.bot.get_updates(
  File "/home/nizomjon/PycharmProjects/Tiu_bot/.venv/lib/python3.9/site-packages/aiogram/bot/bot.py", line 110, in get_updates
    result = await self.request(api.Methods.GET_UPDATES, payload)
  File "/home/nizomjon/PycharmProjects/Tiu_bot/.venv/lib/python3.9/site-packages/aiogram/bot/base.py", line 236, in request
    return await api.make_request(await self.get_session(), self.server, self.__token, method, data, files,
  File "/home/nizomjon/PycharmProjects/Tiu_bot/.venv/lib/python3.9/site-packages/aiogram/bot/api.py", line 142, in make_request
    raise exceptions.NetworkError(f"aiohttp client throws an error: {e.__class__.__name__}: {e}")
aiogram.utils.exceptions.NetworkError: Aiohttp client throws an error: ClientConnectorError: Cannot connect to host api.telegram.org:443 ssl:default [Temporary failure in name resolution]
2025-10-21 00:56:54,273 - aiogram.dispatcher.dispatcher - ERROR - Cause exception while getting updates.
Traceback (most recent call last):
  File "/home/nizomjon/PycharmProjects/Tiu_bot/.venv/lib/python3.9/site-packages/aiohttp/connector.py", line 1155, in _create_direct_connection
    hosts = await asyncio.shield(host_resolved)
  File "/home/nizomjon/PycharmProjects/Tiu_bot/.venv/lib/python3.9/site-packages/aiohttp/connector.py", line 874, in _resolve_host
    addrs = await self._resolver.resolve(host, port, family=self._family)
  File "/home/nizomjon/PycharmProjects/Tiu_bot/.venv/lib/python3.9/site-packages/aiohttp/resolver.py", line 33, in resolve
    infos = await self._loop.getaddrinfo(
  File "/usr/local/lib/python3.9/asyncio/base_events.py", line 856, in getaddrinfo
    return await self.run_in_executor(
  File "/usr/local/lib/python3.9/concurrent/futures/thread.py", line 58, in run
    result = self.fn(*self.args, **self.kwargs)
  File "/usr/local/lib/python3.9/socket.py", line 954, in getaddrinfo
    for res in _socket.getaddrinfo(host, port, family, type, proto, flags):
socket.gaierror: [Errno -3] Temporary failure in name resolution

The above exception was the direct cause of the following exception:

Traceback (most recent call last):
  File "/home/nizomjon/PycharmProjects/Tiu_bot/.venv/lib/python3.9/site-packages/aiogram/bot/api.py", line 139, in make_request
    async with session.post(url, data=req, **kwargs) as response:
  File "/home/nizomjon/PycharmProjects/Tiu_bot/.venv/lib/python3.9/site-packages/aiohttp/client.py", line 1167, in __aenter__
    self._resp = await self._coro
  File "/home/nizomjon/PycharmProjects/Tiu_bot/.venv/lib/python3.9/site-packages/aiohttp/client.py", line 562, in _request
    conn = await self._connector.connect(
  File "/home/nizomjon/PycharmProjects/Tiu_bot/.venv/lib/python3.9/site-packages/aiohttp/connector.py", line 540, in connect
    proto = await self._create_connection(req, traces, timeout)
  File "/home/nizomjon/PycharmProjects/Tiu_bot/.venv/lib/python3.9/site-packages/aiohttp/connector.py", line 901, in _create_connection
    _, proto = await self._create_direct_connection(req, traces, timeout)
  File "/home/nizomjon/PycharmProjects/Tiu_bot/.venv/lib/python3.9/site-packages/aiohttp/connector.py", line 1169, in _create_direct_connection
    raise ClientConnectorError(req.connection_key, exc) from exc
aiohttp.client_exceptions.ClientConnectorError: Cannot connect to host api.telegram.org:443 ssl:default [Temporary failure in name resolution]

During handling of the above exception, another exception occurred:

Traceback (most recent call last):
  File "/home/nizomjon/PycharmProjects/Tiu_bot/.venv/lib/python3.9/site-packages/aiogram/dispatcher/dispatcher.py", line 381, in start_polling
    updates = await self.bot.get_updates(
  File "/home/nizomjon/PycharmProjects/Tiu_bot/.venv/lib/python3.9/site-packages/aiogram/bot/bot.py", line 110, in get_updates
    result = await self.request(api.Methods.GET_UPDATES, payload)
  File "/home/nizomjon/PycharmProjects/Tiu_bot/.venv/lib/python3.9/site-packages/aiogram/bot/base.py", line 236, in request
    return await api.make_request(await self.get_session(), self.server, self.__token, method, data, files,
  File "/home/nizomjon/PycharmProjects/Tiu_bot/.venv/lib/python3.9/site-packages/aiogram/bot/api.py", line 142, in make_request
    raise exceptions.NetworkError(f"aiohttp client throws an error: {e.__class__.__name__}: {e}")
aiogram.utils.exceptions.NetworkError: Aiohttp client throws an error: ClientConnectorError: Cannot connect to host api.telegram.org:443 ssl:default [Temporary failure in name resolution]
2025-10-21 00:56:59,280 - aiogram.dispatcher.dispatcher - ERROR - Cause exception while getting updates.
Traceback (most recent call last):
  File "/home/nizomjon/PycharmProjects/Tiu_bot/.venv/lib/python3.9/site-packages/aiohttp/connector.py", line 1155, in _create_direct_connection
    hosts = await asyncio.shield(host_resolved)
  File "/home/nizomjon/PycharmProjects/Tiu_bot/.venv/lib/python3.9/site-packages/aiohttp/connector.py", line 874, in _resolve_host
    addrs = await self._resolver.resolve(host, port, family=self._family)
  File "/home/nizomjon/PycharmProjects/Tiu_bot/.venv/lib/python3.9/site-packages/aiohttp/resolver.py", line 33, in resolve
    infos = await self._loop.getaddrinfo(
  File "/usr/local/lib/python3.9/asyncio/base_events.py", line 856, in getaddrinfo
    return await self.run_in_executor(
  File "/usr/local/lib/python3.9/concurrent/futures/thread.py", line 58, in run
    result = self.fn(*self.args, **self.kwargs)
  File "/usr/local/lib/python3.9/socket.py", line 954, in getaddrinfo
    for res in _socket.getaddrinfo(host, port, family, type, proto, flags):
socket.gaierror: [Errno -3] Temporary failure in name resolution

The above exception was the direct cause of the following exception:

Traceback (most recent call last):
  File "/home/nizomjon/PycharmProjects/Tiu_bot/.venv/lib/python3.9/site-packages/aiogram/bot/api.py", line 139, in make_request
    async with session.post(url, data=req, **kwargs) as response:
  File "/home/nizomjon/PycharmProjects/Tiu_bot/.venv/lib/python3.9/site-packages/aiohttp/client.py", line 1167, in __aenter__
    self._resp = await self._coro
  File "/home/nizomjon/PycharmProjects/Tiu_bot/.venv/lib/python3.9/site-packages/aiohttp/client.py", line 562, in _request
    conn = await self._connector.connect(
  File "/home/nizomjon/PycharmProjects/Tiu_bot/.venv/lib/python3.9/site-packages/aiohttp/connector.py", line 540, in connect
    proto = await self._create_connection(req, traces, timeout)
  File "/home/nizomjon/PycharmProjects/Tiu_bot/.venv/lib/python3.9/site-packages/aiohttp/connector.py", line 901, in _create_connection
    _, proto = await self._create_direct_connection(req, traces, timeout)
  File "/home/nizomjon/PycharmProjects/Tiu_bot/.venv/lib/python3.9/site-packages/aiohttp/connector.py", line 1169, in _create_direct_connection
    raise ClientConnectorError(req.connection_key, exc) from exc
aiohttp.client_exceptions.ClientConnectorError: Cannot connect to host api.telegram.org:443 ssl:default [Temporary failure in name resolution]

During handling of the above exception, another exception occurred:

Traceback (most recent call last):
  File "/home/nizomjon/PycharmProjects/Tiu_bot/.venv/lib/python3.9/site-packages/aiogram/dispatcher/dispatcher.py", line 381, in start_polling
    updates = await self.bot.get_updates(
  File "/home/nizomjon/PycharmProjects/Tiu_bot/.venv/lib/python3.9/site-packages/aiogram/bot/bot.py", line 110, in get_updates
    result = await self.request(api.Methods.GET_UPDATES, payload)
  File "/home/nizomjon/PycharmProjects/Tiu_bot/.venv/lib/python3.9/site-packages/aiogram/bot/base.py", line 236, in request
    return await api.make_request(await self.get_session(), self.server, self.__token, method, data, files,
  File "/home/nizomjon/PycharmProjects/Tiu_bot/.venv/lib/python3.9/site-packages/aiogram/bot/api.py", line 142, in make_request
    raise exceptions.NetworkError(f"aiohttp client throws an error: {e.__class__.__name__}: {e}")
aiogram.utils.exceptions.NetworkError: Aiohttp client throws an error: ClientConnectorError: Cannot connect to host api.telegram.org:443 ssl:default [Temporary failure in name resolution]
2025-10-21 00:57:04,284 - aiogram.dispatcher.dispatcher - ERROR - Cause exception while getting updates.
Traceback (most recent call last):
  File "/home/nizomjon/PycharmProjects/Tiu_bot/.venv/lib/python3.9/site-packages/aiohttp/connector.py", line 1155, in _create_direct_connection
    hosts = await asyncio.shield(host_resolved)
  File "/home/nizomjon/PycharmProjects/Tiu_bot/.venv/lib/python3.9/site-packages/aiohttp/connector.py", line 874, in _resolve_host
    addrs = await self._resolver.resolve(host, port, family=self._family)
  File "/home/nizomjon/PycharmProjects/Tiu_bot/.venv/lib/python3.9/site-packages/aiohttp/resolver.py", line 33, in resolve
    infos = await self._loop.getaddrinfo(
  File "/usr/local/lib/python3.9/asyncio/base_events.py", line 856, in getaddrinfo
    return await self.run_in_executor(
  File "/usr/local/lib/python3.9/concurrent/futures/thread.py", line 58, in run
    result = self.fn(*self.args, **self.kwargs)
  File "/usr/local/lib/python3.9/socket.py", line 954, in getaddrinfo
    for res in _socket.getaddrinfo(host, port, family, type, proto, flags):
socket.gaierror: [Errno -3] Temporary failure in name resolution

The above exception was the direct cause of the following exception:

Traceback (most recent call last):
  File "/home/nizomjon/PycharmProjects/Tiu_bot/.venv/lib/python3.9/site-packages/aiogram/bot/api.py", line 139, in make_request
    async with session.post(url, data=req, **kwargs) as response:
  File "/home/nizomjon/PycharmProjects/Tiu_bot/.venv/lib/python3.9/site-packages/aiohttp/client.py", line 1167, in __aenter__
    self._resp = await self._coro
  File "/home/nizomjon/PycharmProjects/Tiu_bot/.venv/lib/python3.9/site-packages/aiohttp/client.py", line 562, in _request
    conn = await self._connector.connect(
  File "/home/nizomjon/PycharmProjects/Tiu_bot/.venv/lib/python3.9/site-packages/aiohttp/connector.py", line 540, in connect
    proto = await self._create_connection(req, traces, timeout)
  File "/home/nizomjon/PycharmProjects/Tiu_bot/.venv/lib/python3.9/site-packages/aiohttp/connector.py", line 901, in _create_connection
    _, proto = await self._create_direct_connection(req, traces, timeout)
  File "/home/nizomjon/PycharmProjects/Tiu_bot/.venv/lib/python3.9/site-packages/aiohttp/connector.py", line 1169, in _create_direct_connection
    raise ClientConnectorError(req.connection_key, exc) from exc
aiohttp.client_exceptions.ClientConnectorError: Cannot connect to host api.telegram.org:443 ssl:default [Temporary failure in name resolution]

During handling of the above exception, another exception occurred:

Traceback (most recent call last):
  File "/home/nizomjon/PycharmProjects/Tiu_bot/.venv/lib/python3.9/site-packages/aiogram/dispatcher/dispatcher.py", line 381, in start_polling
    updates = await self.bot.get_updates(
  File "/home/nizomjon/PycharmProjects/Tiu_bot/.venv/lib/python3.9/site-packages/aiogram/bot/bot.py", line 110, in get_updates
    result = await self.request(api.Methods.GET_UPDATES, payload)
  File "/home/nizomjon/PycharmProjects/Tiu_bot/.venv/lib/python3.9/site-packages/aiogram/bot/base.py", line 236, in request
    return await api.make_request(await self.get_session(), self.server, self.__token, method, data, files,
  File "/home/nizomjon/PycharmProjects/Tiu_bot/.venv/lib/python3.9/site-packages/aiogram/bot/api.py", line 142, in make_request
    raise exceptions.NetworkError(f"aiohttp client throws an error: {e.__class__.__name__}: {e}")
aiogram.utils.exceptions.NetworkError: Aiohttp client throws an error: ClientConnectorError: Cannot connect to host api.telegram.org:443 ssl:default [Temporary failure in name resolution]
2025-10-21 00:57:09,288 - aiogram.dispatcher.dispatcher - ERROR - Cause exception while getting updates.
Traceback (most recent call last):
  File "/home/nizomjon/PycharmProjects/Tiu_bot/.venv/lib/python3.9/site-packages/aiohttp/connector.py", line 1155, in _create_direct_connection
    hosts = await asyncio.shield(host_resolved)
  File "/home/nizomjon/PycharmProjects/Tiu_bot/.venv/lib/python3.9/site-packages/aiohttp/connector.py", line 874, in _resolve_host
    addrs = await self._resolver.resolve(host, port, family=self._family)
  File "/home/nizomjon/PycharmProjects/Tiu_bot/.venv/lib/python3.9/site-packages/aiohttp/resolver.py", line 33, in resolve
    infos = await self._loop.getaddrinfo(
  File "/usr/local/lib/python3.9/asyncio/base_events.py", line 856, in getaddrinfo
    return await self.run_in_executor(
  File "/usr/local/lib/python3.9/concurrent/futures/thread.py", line 58, in run
    result = self.fn(*self.args, **self.kwargs)
  File "/usr/local/lib/python3.9/socket.py", line 954, in getaddrinfo
    for res in _socket.getaddrinfo(host, port, family, type, proto, flags):
socket.gaierror: [Errno -3] Temporary failure in name resolution

The above exception was the direct cause of the following exception:

Traceback (most recent call last):
  File "/home/nizomjon/PycharmProjects/Tiu_bot/.venv/lib/python3.9/site-packages/aiogram/bot/api.py", line 139, in make_request
    async with session.post(url, data=req, **kwargs) as response:
  File "/home/nizomjon/PycharmProjects/Tiu_bot/.venv/lib/python3.9/site-packages/aiohttp/client.py", line 1167, in __aenter__
    self._resp = await self._coro
  File "/home/nizomjon/PycharmProjects/Tiu_bot/.venv/lib/python3.9/site-packages/aiohttp/client.py", line 562, in _request
    conn = await self._connector.connect(
  File "/home/nizomjon/PycharmProjects/Tiu_bot/.venv/lib/python3.9/site-packages/aiohttp/connector.py", line 540, in connect
    proto = await self._create_connection(req, traces, timeout)
  File "/home/nizomjon/PycharmProjects/Tiu_bot/.venv/lib/python3.9/site-packages/aiohttp/connector.py", line 901, in _create_connection
    _, proto = await self._create_direct_connection(req, traces, timeout)
  File "/home/nizomjon/PycharmProjects/Tiu_bot/.venv/lib/python3.9/site-packages/aiohttp/connector.py", line 1169, in _create_direct_connection
    raise ClientConnectorError(req.connection_key, exc) from exc
aiohttp.client_exceptions.ClientConnectorError: Cannot connect to host api.telegram.org:443 ssl:default [Temporary failure in name resolution]

During handling of the above exception, another exception occurred:

Traceback (most recent call last):
  File "/home/nizomjon/PycharmProjects/Tiu_bot/.venv/lib/python3.9/site-packages/aiogram/dispatcher/dispatcher.py", line 381, in start_polling
    updates = await self.bot.get_updates(
  File "/home/nizomjon/PycharmProjects/Tiu_bot/.venv/lib/python3.9/site-packages/aiogram/bot/bot.py", line 110, in get_updates
    result = await self.request(api.Methods.GET_UPDATES, payload)
  File "/home/nizomjon/PycharmProjects/Tiu_bot/.venv/lib/python3.9/site-packages/aiogram/bot/base.py", line 236, in request
    return await api.make_request(await self.get_session(), self.server, self.__token, method, data, files,
  File "/home/nizomjon/PycharmProjects/Tiu_bot/.venv/lib/python3.9/site-packages/aiogram/bot/api.py", line 142, in make_request
    raise exceptions.NetworkError(f"aiohttp client throws an error: {e.__class__.__name__}: {e}")
aiogram.utils.exceptions.NetworkError: Aiohttp client throws an error: ClientConnectorError: Cannot connect to host api.telegram.org:443 ssl:default [Temporary failure in name resolution]
2025-10-21 00:57:14,293 - aiogram.dispatcher.dispatcher - ERROR - Cause exception while getting updates.
Traceback (most recent call last):
  File "/home/nizomjon/PycharmProjects/Tiu_bot/.venv/lib/python3.9/site-packages/aiohttp/connector.py", line 1155, in _create_direct_connection
    hosts = await asyncio.shield(host_resolved)
  File "/home/nizomjon/PycharmProjects/Tiu_bot/.venv/lib/python3.9/site-packages/aiohttp/connector.py", line 874, in _resolve_host
    addrs = await self._resolver.resolve(host, port, family=self._family)
  File "/home/nizomjon/PycharmProjects/Tiu_bot/.venv/lib/python3.9/site-packages/aiohttp/resolver.py", line 33, in resolve
    infos = await self._loop.getaddrinfo(
  File "/usr/local/lib/python3.9/asyncio/base_events.py", line 856, in getaddrinfo
    return await self.run_in_executor(
  File "/usr/local/lib/python3.9/concurrent/futures/thread.py", line 58, in run
    result = self.fn(*self.args, **self.kwargs)
  File "/usr/local/lib/python3.9/socket.py", line 954, in getaddrinfo
    for res in _socket.getaddrinfo(host, port, family, type, proto, flags):
socket.gaierror: [Errno -3] Temporary failure in name resolution

The above exception was the direct cause of the following exception:

Traceback (most recent call last):
  File "/home/nizomjon/PycharmProjects/Tiu_bot/.venv/lib/python3.9/site-packages/aiogram/bot/api.py", line 139, in make_request
    async with session.post(url, data=req, **kwargs) as response:
  File "/home/nizomjon/PycharmProjects/Tiu_bot/.venv/lib/python3.9/site-packages/aiohttp/client.py", line 1167, in __aenter__
    self._resp = await self._coro
  File "/home/nizomjon/PycharmProjects/Tiu_bot/.venv/lib/python3.9/site-packages/aiohttp/client.py", line 562, in _request
    conn = await self._connector.connect(
  File "/home/nizomjon/PycharmProjects/Tiu_bot/.venv/lib/python3.9/site-packages/aiohttp/connector.py", line 540, in connect
    proto = await self._create_connection(req, traces, timeout)
  File "/home/nizomjon/PycharmProjects/Tiu_bot/.venv/lib/python3.9/site-packages/aiohttp/connector.py", line 901, in _create_connection
    _, proto = await self._create_direct_connection(req, traces, timeout)
  File "/home/nizomjon/PycharmProjects/Tiu_bot/.venv/lib/python3.9/site-packages/aiohttp/connector.py", line 1169, in _create_direct_connection
    raise ClientConnectorError(req.connection_key, exc) from exc
aiohttp.client_exceptions.ClientConnectorError: Cannot connect to host api.telegram.org:443 ssl:default [Temporary failure in name resolution]

During handling of the above exception, another exception occurred:

Traceback (most recent call last):
  File "/home/nizomjon/PycharmProjects/Tiu_bot/.venv/lib/python3.9/site-packages/aiogram/dispatcher/dispatcher.py", line 381, in start_polling
    updates = await self.bot.get_updates(
  File "/home/nizomjon/PycharmProjects/Tiu_bot/.venv/lib/python3.9/site-packages/aiogram/bot/bot.py", line 110, in get_updates
    result = await self.request(api.Methods.GET_UPDATES, payload)
  File "/home/nizomjon/PycharmProjects/Tiu_bot/.venv/lib/python3.9/site-packages/aiogram/bot/base.py", line 236, in request
    return await api.make_request(await self.get_session(), self.server, self.__token, method, data, files,
  File "/home/nizomjon/PycharmProjects/Tiu_bot/.venv/lib/python3.9/site-packages/aiogram/bot/api.py", line 142, in make_request
    raise exceptions.NetworkError(f"aiohttp client throws an error: {e.__class__.__name__}: {e}")
aiogram.utils.exceptions.NetworkError: Aiohttp client throws an error: ClientConnectorError: Cannot connect to host api.telegram.org:443 ssl:default [Temporary failure in name resolution]
2025-10-21 00:57:19,301 - aiogram.dispatcher.dispatcher - ERROR - Cause exception while getting updates.
Traceback (most recent call last):
  File "/home/nizomjon/PycharmProjects/Tiu_bot/.venv/lib/python3.9/site-packages/aiohttp/connector.py", line 1155, in _create_direct_connection
    hosts = await asyncio.shield(host_resolved)
  File "/home/nizomjon/PycharmProjects/Tiu_bot/.venv/lib/python3.9/site-packages/aiohttp/connector.py", line 874, in _resolve_host
    addrs = await self._resolver.resolve(host, port, family=self._family)
  File "/home/nizomjon/PycharmProjects/Tiu_bot/.venv/lib/python3.9/site-packages/aiohttp/resolver.py", line 33, in resolve
    infos = await self._loop.getaddrinfo(
  File "/usr/local/lib/python3.9/asyncio/base_events.py", line 856, in getaddrinfo
    return await self.run_in_executor(
  File "/usr/local/lib/python3.9/concurrent/futures/thread.py", line 58, in run
    result = self.fn(*self.args, **self.kwargs)
  File "/usr/local/lib/python3.9/socket.py", line 954, in getaddrinfo
    for res in _socket.getaddrinfo(host, port, family, type, proto, flags):
socket.gaierror: [Errno -3] Temporary failure in name resolution

The above exception was the direct cause of the following exception:

Traceback (most recent call last):
  File "/home/nizomjon/PycharmProjects/Tiu_bot/.venv/lib/python3.9/site-packages/aiogram/bot/api.py", line 139, in make_request
    async with session.post(url, data=req, **kwargs) as response:
  File "/home/nizomjon/PycharmProjects/Tiu_bot/.venv/lib/python3.9/site-packages/aiohttp/client.py", line 1167, in __aenter__
    self._resp = await self._coro
  File "/home/nizomjon/PycharmProjects/Tiu_bot/.venv/lib/python3.9/site-packages/aiohttp/client.py", line 562, in _request
    conn = await self._connector.connect(
  File "/home/nizomjon/PycharmProjects/Tiu_bot/.venv/lib/python3.9/site-packages/aiohttp/connector.py", line 540, in connect
    proto = await self._create_connection(req, traces, timeout)
  File "/home/nizomjon/PycharmProjects/Tiu_bot/.venv/lib/python3.9/site-packages/aiohttp/connector.py", line 901, in _create_connection
    _, proto = await self._create_direct_connection(req, traces, timeout)
  File "/home/nizomjon/PycharmProjects/Tiu_bot/.venv/lib/python3.9/site-packages/aiohttp/connector.py", line 1169, in _create_direct_connection
    raise ClientConnectorError(req.connection_key, exc) from exc
aiohttp.client_exceptions.ClientConnectorError: Cannot connect to host api.telegram.org:443 ssl:default [Temporary failure in name resolution]

During handling of the above exception, another exception occurred:

Traceback (most recent call last):
  File "/home/nizomjon/PycharmProjects/Tiu_bot/.venv/lib/python3.9/site-packages/aiogram/dispatcher/dispatcher.py", line 381, in start_polling
    updates = await self.bot.get_updates(
  File "/home/nizomjon/PycharmProjects/Tiu_bot/.venv/lib/python3.9/site-packages/aiogram/bot/bot.py", line 110, in get_updates
    result = await self.request(api.Methods.GET_UPDATES, payload)
  File "/home/nizomjon/PycharmProjects/Tiu_bot/.venv/lib/python3.9/site-packages/aiogram/bot/base.py", line 236, in request
    return await api.make_request(await self.get_session(), self.server, self.__token, method, data, files,
  File "/home/nizomjon/PycharmProjects/Tiu_bot/.venv/lib/python3.9/site-packages/aiogram/bot/api.py", line 142, in make_request
    raise exceptions.NetworkError(f"aiohttp client throws an error: {e.__class__.__name__}: {e}")
aiogram.utils.exceptions.NetworkError: Aiohttp client throws an error: ClientConnectorError: Cannot connect to host api.telegram.org:443 ssl:default [Temporary failure in name resolution]
2025-10-21 00:57:24,308 - aiogram.dispatcher.dispatcher - ERROR - Cause exception while getting updates.
Traceback (most recent call last):
  File "/home/nizomjon/PycharmProjects/Tiu_bot/.venv/lib/python3.9/site-packages/aiohttp/connector.py", line 1155, in _create_direct_connection
    hosts = await asyncio.shield(host_resolved)
  File "/home/nizomjon/PycharmProjects/Tiu_bot/.venv/lib/python3.9/site-packages/aiohttp/connector.py", line 874, in _resolve_host
    addrs = await self._resolver.resolve(host, port, family=self._family)
  File "/home/nizomjon/PycharmProjects/Tiu_bot/.venv/lib/python3.9/site-packages/aiohttp/resolver.py", line 33, in resolve
    infos = await self._loop.getaddrinfo(
  File "/usr/local/lib/python3.9/asyncio/base_events.py", line 856, in getaddrinfo
    return await self.run_in_executor(
  File "/usr/local/lib/python3.9/concurrent/futures/thread.py", line 58, in run
    result = self.fn(*self.args, **self.kwargs)
  File "/usr/local/lib/python3.9/socket.py", line 954, in getaddrinfo
    for res in _socket.getaddrinfo(host, port, family, type, proto, flags):
socket.gaierror: [Errno -3] Temporary failure in name resolution

The above exception was the direct cause of the following exception:

Traceback (most recent call last):
  File "/home/nizomjon/PycharmProjects/Tiu_bot/.venv/lib/python3.9/site-packages/aiogram/bot/api.py", line 139, in make_request
    async with session.post(url, data=req, **kwargs) as response:
  File "/home/nizomjon/PycharmProjects/Tiu_bot/.venv/lib/python3.9/site-packages/aiohttp/client.py", line 1167, in __aenter__
    self._resp = await self._coro
  File "/home/nizomjon/PycharmProjects/Tiu_bot/.venv/lib/python3.9/site-packages/aiohttp/client.py", line 562, in _request
    conn = await self._connector.connect(
  File "/home/nizomjon/PycharmProjects/Tiu_bot/.venv/lib/python3.9/site-packages/aiohttp/connector.py", line 540, in connect
    proto = await self._create_connection(req, traces, timeout)
  File "/home/nizomjon/PycharmProjects/Tiu_bot/.venv/lib/python3.9/site-packages/aiohttp/connector.py", line 901, in _create_connection
    _, proto = await self._create_direct_connection(req, traces, timeout)
  File "/home/nizomjon/PycharmProjects/Tiu_bot/.venv/lib/python3.9/site-packages/aiohttp/connector.py", line 1169, in _create_direct_connection
    raise ClientConnectorError(req.connection_key, exc) from exc
aiohttp.client_exceptions.ClientConnectorError: Cannot connect to host api.telegram.org:443 ssl:default [Temporary failure in name resolution]

During handling of the above exception, another exception occurred:

Traceback (most recent call last):
  File "/home/nizomjon/PycharmProjects/Tiu_bot/.venv/lib/python3.9/site-packages/aiogram/dispatcher/dispatcher.py", line 381, in start_polling
    updates = await self.bot.get_updates(
  File "/home/nizomjon/PycharmProjects/Tiu_bot/.venv/lib/python3.9/site-packages/aiogram/bot/bot.py", line 110, in get_updates
    result = await self.request(api.Methods.GET_UPDATES, payload)
  File "/home/nizomjon/PycharmProjects/Tiu_bot/.venv/lib/python3.9/site-packages/aiogram/bot/base.py", line 236, in request
    return await api.make_request(await self.get_session(), self.server, self.__token, method, data, files,
  File "/home/nizomjon/PycharmProjects/Tiu_bot/.venv/lib/python3.9/site-packages/aiogram/bot/api.py", line 142, in make_request
    raise exceptions.NetworkError(f"aiohttp client throws an error: {e.__class__.__name__}: {e}")
aiogram.utils.exceptions.NetworkError: Aiohttp client throws an error: ClientConnectorError: Cannot connect to host api.telegram.org:443 ssl:default [Temporary failure in name resolution]
2025-10-21 00:57:29,315 - aiogram.dispatcher.dispatcher - ERROR - Cause exception while getting updates.
Traceback (most recent call last):
  File "/home/nizomjon/PycharmProjects/Tiu_bot/.venv/lib/python3.9/site-packages/aiohttp/connector.py", line 1155, in _create_direct_connection
    hosts = await asyncio.shield(host_resolved)
  File "/home/nizomjon/PycharmProjects/Tiu_bot/.venv/lib/python3.9/site-packages/aiohttp/connector.py", line 874, in _resolve_host
    addrs = await self._resolver.resolve(host, port, family=self._family)
  File "/home/nizomjon/PycharmProjects/Tiu_bot/.venv/lib/python3.9/site-packages/aiohttp/resolver.py", line 33, in resolve
    infos = await self._loop.getaddrinfo(
  File "/usr/local/lib/python3.9/asyncio/base_events.py", line 856, in getaddrinfo
    return await self.run_in_executor(
  File "/usr/local/lib/python3.9/concurrent/futures/thread.py", line 58, in run
    result = self.fn(*self.args, **self.kwargs)
  File "/usr/local/lib/python3.9/socket.py", line 954, in getaddrinfo
    for res in _socket.getaddrinfo(host, port, family, type, proto, flags):
socket.gaierror: [Errno -3] Temporary failure in name resolution

The above exception was the direct cause of the following exception:

Traceback (most recent call last):
  File "/home/nizomjon/PycharmProjects/Tiu_bot/.venv/lib/python3.9/site-packages/aiogram/bot/api.py", line 139, in make_request
    async with session.post(url, data=req, **kwargs) as response:
  File "/home/nizomjon/PycharmProjects/Tiu_bot/.venv/lib/python3.9/site-packages/aiohttp/client.py", line 1167, in __aenter__
    self._resp = await self._coro
  File "/home/nizomjon/PycharmProjects/Tiu_bot/.venv/lib/python3.9/site-packages/aiohttp/client.py", line 562, in _request
    conn = await self._connector.connect(
  File "/home/nizomjon/PycharmProjects/Tiu_bot/.venv/lib/python3.9/site-packages/aiohttp/connector.py", line 540, in connect
    proto = await self._create_connection(req, traces, timeout)
  File "/home/nizomjon/PycharmProjects/Tiu_bot/.venv/lib/python3.9/site-packages/aiohttp/connector.py", line 901, in _create_connection
    _, proto = await self._create_direct_connection(req, traces, timeout)
  File "/home/nizomjon/PycharmProjects/Tiu_bot/.venv/lib/python3.9/site-packages/aiohttp/connector.py", line 1169, in _create_direct_connection
    raise ClientConnectorError(req.connection_key, exc) from exc
aiohttp.client_exceptions.ClientConnectorError: Cannot connect to host api.telegram.org:443 ssl:default [Temporary failure in name resolution]

During handling of the above exception, another exception occurred:

Traceback (most recent call last):
  File "/home/nizomjon/PycharmProjects/Tiu_bot/.venv/lib/python3.9/site-packages/aiogram/dispatcher/dispatcher.py", line 381, in start_polling
    updates = await self.bot.get_updates(
  File "/home/nizomjon/PycharmProjects/Tiu_bot/.venv/lib/python3.9/site-packages/aiogram/bot/bot.py", line 110, in get_updates
    result = await self.request(api.Methods.GET_UPDATES, payload)
  File "/home/nizomjon/PycharmProjects/Tiu_bot/.venv/lib/python3.9/site-packages/aiogram/bot/base.py", line 236, in request
    return await api.make_request(await self.get_session(), self.server, self.__token, method, data, files,
  File "/home/nizomjon/PycharmProjects/Tiu_bot/.venv/lib/python3.9/site-packages/aiogram/bot/api.py", line 142, in make_request
    raise exceptions.NetworkError(f"aiohttp client throws an error: {e.__class__.__name__}: {e}")
aiogram.utils.exceptions.NetworkError: Aiohttp client throws an error: ClientConnectorError: Cannot connect to host api.telegram.org:443 ssl:default [Temporary failure in name resolution]
2025-10-21 00:57:34,321 - aiogram.dispatcher.dispatcher - ERROR - Cause exception while getting updates.
Traceback (most recent call last):
  File "/home/nizomjon/PycharmProjects/Tiu_bot/.venv/lib/python3.9/site-packages/aiohttp/connector.py", line 1155, in _create_direct_connection
    hosts = await asyncio.shield(host_resolved)
  File "/home/nizomjon/PycharmProjects/Tiu_bot/.venv/lib/python3.9/site-packages/aiohttp/connector.py", line 874, in _resolve_host
    addrs = await self._resolver.resolve(host, port, family=self._family)
  File "/home/nizomjon/PycharmProjects/Tiu_bot/.venv/lib/python3.9/site-packages/aiohttp/resolver.py", line 33, in resolve
    infos = await self._loop.getaddrinfo(
  File "/usr/local/lib/python3.9/asyncio/base_events.py", line 856, in getaddrinfo
    return await self.run_in_executor(
  File "/usr/local/lib/python3.9/concurrent/futures/thread.py", line 58, in run
    result = self.fn(*self.args, **self.kwargs)
  File "/usr/local/lib/python3.9/socket.py", line 954, in getaddrinfo
    for res in _socket.getaddrinfo(host, port, family, type, proto, flags):
socket.gaierror: [Errno -3] Temporary failure in name resolution

The above exception was the direct cause of the following exception:

Traceback (most recent call last):
  File "/home/nizomjon/PycharmProjects/Tiu_bot/.venv/lib/python3.9/site-packages/aiogram/bot/api.py", line 139, in make_request
    async with session.post(url, data=req, **kwargs) as response:
  File "/home/nizomjon/PycharmProjects/Tiu_bot/.venv/lib/python3.9/site-packages/aiohttp/client.py", line 1167, in __aenter__
    self._resp = await self._coro
  File "/home/nizomjon/PycharmProjects/Tiu_bot/.venv/lib/python3.9/site-packages/aiohttp/client.py", line 562, in _request
    conn = await self._connector.connect(
  File "/home/nizomjon/PycharmProjects/Tiu_bot/.venv/lib/python3.9/site-packages/aiohttp/connector.py", line 540, in connect
    proto = await self._create_connection(req, traces, timeout)
  File "/home/nizomjon/PycharmProjects/Tiu_bot/.venv/lib/python3.9/site-packages/aiohttp/connector.py", line 901, in _create_connection
    _, proto = await self._create_direct_connection(req, traces, timeout)
  File "/home/nizomjon/PycharmProjects/Tiu_bot/.venv/lib/python3.9/site-packages/aiohttp/connector.py", line 1169, in _create_direct_connection
    raise ClientConnectorError(req.connection_key, exc) from exc
aiohttp.client_exceptions.ClientConnectorError: Cannot connect to host api.telegram.org:443 ssl:default [Temporary failure in name resolution]

During handling of the above exception, another exception occurred:

Traceback (most recent call last):
  File "/home/nizomjon/PycharmProjects/Tiu_bot/.venv/lib/python3.9/site-packages/aiogram/dispatcher/dispatcher.py", line 381, in start_polling
    updates = await self.bot.get_updates(
  File "/home/nizomjon/PycharmProjects/Tiu_bot/.venv/lib/python3.9/site-packages/aiogram/bot/bot.py", line 110, in get_updates
    result = await self.request(api.Methods.GET_UPDATES, payload)
  File "/home/nizomjon/PycharmProjects/Tiu_bot/.venv/lib/python3.9/site-packages/aiogram/bot/base.py", line 236, in request
    return await api.make_request(await self.get_session(), self.server, self.__token, method, data, files,
  File "/home/nizomjon/PycharmProjects/Tiu_bot/.venv/lib/python3.9/site-packages/aiogram/bot/api.py", line 142, in make_request
    raise exceptions.NetworkError(f"aiohttp client throws an error: {e.__class__.__name__}: {e}")
aiogram.utils.exceptions.NetworkError: Aiohttp client throws an error: ClientConnectorError: Cannot connect to host api.telegram.org:443 ssl:default [Temporary failure in name resolution]
2025-10-21 00:57:39,329 - aiogram.dispatcher.dispatcher - ERROR - Cause exception while getting updates.
Traceback (most recent call last):
  File "/home/nizomjon/PycharmProjects/Tiu_bot/.venv/lib/python3.9/site-packages/aiohttp/connector.py", line 1155, in _create_direct_connection
    hosts = await asyncio.shield(host_resolved)
  File "/home/nizomjon/PycharmProjects/Tiu_bot/.venv/lib/python3.9/site-packages/aiohttp/connector.py", line 874, in _resolve_host
    addrs = await self._resolver.resolve(host, port, family=self._family)
  File "/home/nizomjon/PycharmProjects/Tiu_bot/.venv/lib/python3.9/site-packages/aiohttp/resolver.py", line 33, in resolve
    infos = await self._loop.getaddrinfo(
  File "/usr/local/lib/python3.9/asyncio/base_events.py", line 856, in getaddrinfo
    return await self.run_in_executor(
  File "/usr/local/lib/python3.9/concurrent/futures/thread.py", line 58, in run
    result = self.fn(*self.args, **self.kwargs)
  File "/usr/local/lib/python3.9/socket.py", line 954, in getaddrinfo
    for res in _socket.getaddrinfo(host, port, family, type, proto, flags):
socket.gaierror: [Errno -3] Temporary failure in name resolution

The above exception was the direct cause of the following exception:

Traceback (most recent call last):
  File "/home/nizomjon/PycharmProjects/Tiu_bot/.venv/lib/python3.9/site-packages/aiogram/bot/api.py", line 139, in make_request
    async with session.post(url, data=req, **kwargs) as response:
  File "/home/nizomjon/PycharmProjects/Tiu_bot/.venv/lib/python3.9/site-packages/aiohttp/client.py", line 1167, in __aenter__
    self._resp = await self._coro
  File "/home/nizomjon/PycharmProjects/Tiu_bot/.venv/lib/python3.9/site-packages/aiohttp/client.py", line 562, in _request
    conn = await self._connector.connect(
  File "/home/nizomjon/PycharmProjects/Tiu_bot/.venv/lib/python3.9/site-packages/aiohttp/connector.py", line 540, in connect
    proto = await self._create_connection(req, traces, timeout)
  File "/home/nizomjon/PycharmProjects/Tiu_bot/.venv/lib/python3.9/site-packages/aiohttp/connector.py", line 901, in _create_connection
    _, proto = await self._create_direct_connection(req, traces, timeout)
  File "/home/nizomjon/PycharmProjects/Tiu_bot/.venv/lib/python3.9/site-packages/aiohttp/connector.py", line 1169, in _create_direct_connection
    raise ClientConnectorError(req.connection_key, exc) from exc
aiohttp.client_exceptions.ClientConnectorError: Cannot connect to host api.telegram.org:443 ssl:default [Temporary failure in name resolution]

During handling of the above exception, another exception occurred:

Traceback (most recent call last):
  File "/home/nizomjon/PycharmProjects/Tiu_bot/.venv/lib/python3.9/site-packages/aiogram/dispatcher/dispatcher.py", line 381, in start_polling
    updates = await self.bot.get_updates(
  File "/home/nizomjon/PycharmProjects/Tiu_bot/.venv/lib/python3.9/site-packages/aiogram/bot/bot.py", line 110, in get_updates
    result = await self.request(api.Methods.GET_UPDATES, payload)
  File "/home/nizomjon/PycharmProjects/Tiu_bot/.venv/lib/python3.9/site-packages/aiogram/bot/base.py", line 236, in request
    return await api.make_request(await self.get_session(), self.server, self.__token, method, data, files,
  File "/home/nizomjon/PycharmProjects/Tiu_bot/.venv/lib/python3.9/site-packages/aiogram/bot/api.py", line 142, in make_request
    raise exceptions.NetworkError(f"aiohttp client throws an error: {e.__class__.__name__}: {e}")
aiogram.utils.exceptions.NetworkError: Aiohttp client throws an error: ClientConnectorError: Cannot connect to host api.telegram.org:443 ssl:default [Temporary failure in name resolution]
2025-10-21 00:57:44,336 - aiogram.dispatcher.dispatcher - ERROR - Cause exception while getting updates.
Traceback (most recent call last):
  File "/home/nizomjon/PycharmProjects/Tiu_bot/.venv/lib/python3.9/site-packages/aiohttp/connector.py", line 1155, in _create_direct_connection
    hosts = await asyncio.shield(host_resolved)
  File "/home/nizomjon/PycharmProjects/Tiu_bot/.venv/lib/python3.9/site-packages/aiohttp/connector.py", line 874, in _resolve_host
    addrs = await self._resolver.resolve(host, port, family=self._family)
  File "/home/nizomjon/PycharmProjects/Tiu_bot/.venv/lib/python3.9/site-packages/aiohttp/resolver.py", line 33, in resolve
    infos = await self._loop.getaddrinfo(
  File "/usr/local/lib/python3.9/asyncio/base_events.py", line 856, in getaddrinfo
    return await self.run_in_executor(
  File "/usr/local/lib/python3.9/concurrent/futures/thread.py", line 58, in run
    result = self.fn(*self.args, **self.kwargs)
  File "/usr/local/lib/python3.9/socket.py", line 954, in getaddrinfo
    for res in _socket.getaddrinfo(host, port, family, type, proto, flags):
socket.gaierror: [Errno -3] Temporary failure in name resolution

The above exception was the direct cause of the following exception:

Traceback (most recent call last):
  File "/home/nizomjon/PycharmProjects/Tiu_bot/.venv/lib/python3.9/site-packages/aiogram/bot/api.py", line 139, in make_request
    async with session.post(url, data=req, **kwargs) as response:
  File "/home/nizomjon/PycharmProjects/Tiu_bot/.venv/lib/python3.9/site-packages/aiohttp/client.py", line 1167, in __aenter__
    self._resp = await self._coro
  File "/home/nizomjon/PycharmProjects/Tiu_bot/.venv/lib/python3.9/site-packages/aiohttp/client.py", line 562, in _request
    conn = await self._connector.connect(
  File "/home/nizomjon/PycharmProjects/Tiu_bot/.venv/lib/python3.9/site-packages/aiohttp/connector.py", line 540, in connect
    proto = await self._create_connection(req, traces, timeout)
  File "/home/nizomjon/PycharmProjects/Tiu_bot/.venv/lib/python3.9/site-packages/aiohttp/connector.py", line 901, in _create_connection
    _, proto = await self._create_direct_connection(req, traces, timeout)
  File "/home/nizomjon/PycharmProjects/Tiu_bot/.venv/lib/python3.9/site-packages/aiohttp/connector.py", line 1169, in _create_direct_connection
    raise ClientConnectorError(req.connection_key, exc) from exc
aiohttp.client_exceptions.ClientConnectorError: Cannot connect to host api.telegram.org:443 ssl:default [Temporary failure in name resolution]

During handling of the above exception, another exception occurred:

Traceback (most recent call last):
  File "/home/nizomjon/PycharmProjects/Tiu_bot/.venv/lib/python3.9/site-packages/aiogram/dispatcher/dispatcher.py", line 381, in start_polling
    updates = await self.bot.get_updates(
  File "/home/nizomjon/PycharmProjects/Tiu_bot/.venv/lib/python3.9/site-packages/aiogram/bot/bot.py", line 110, in get_updates
    result = await self.request(api.Methods.GET_UPDATES, payload)
  File "/home/nizomjon/PycharmProjects/Tiu_bot/.venv/lib/python3.9/site-packages/aiogram/bot/base.py", line 236, in request
    return await api.make_request(await self.get_session(), self.server, self.__token, method, data, files,
  File "/home/nizomjon/PycharmProjects/Tiu_bot/.venv/lib/python3.9/site-packages/aiogram/bot/api.py", line 142, in make_request
    raise exceptions.NetworkError(f"aiohttp client throws an error: {e.__class__.__name__}: {e}")
aiogram.utils.exceptions.NetworkError: Aiohttp client throws an error: ClientConnectorError: Cannot connect to host api.telegram.org:443 ssl:default [Temporary failure in name resolution]
2025-10-21 00:57:49,340 - aiogram.dispatcher.dispatcher - ERROR - Cause exception while getting updates.
Traceback (most recent call last):
  File "/home/nizomjon/PycharmProjects/Tiu_bot/.venv/lib/python3.9/site-packages/aiohttp/connector.py", line 1155, in _create_direct_connection
    hosts = await asyncio.shield(host_resolved)
  File "/home/nizomjon/PycharmProjects/Tiu_bot/.venv/lib/python3.9/site-packages/aiohttp/connector.py", line 874, in _resolve_host
    addrs = await self._resolver.resolve(host, port, family=self._family)
  File "/home/nizomjon/PycharmProjects/Tiu_bot/.venv/lib/python3.9/site-packages/aiohttp/resolver.py", line 33, in resolve
    infos = await self._loop.getaddrinfo(
  File "/usr/local/lib/python3.9/asyncio/base_events.py", line 856, in getaddrinfo
    return await self.run_in_executor(
  File "/usr/local/lib/python3.9/concurrent/futures/thread.py", line 58, in run
    result = self.fn(*self.args, **self.kwargs)
  File "/usr/local/lib/python3.9/socket.py", line 954, in getaddrinfo
    for res in _socket.getaddrinfo(host, port, family, type, proto, flags):
socket.gaierror: [Errno -3] Temporary failure in name resolution

The above exception was the direct cause of the following exception:

Traceback (most recent call last):
  File "/home/nizomjon/PycharmProjects/Tiu_bot/.venv/lib/python3.9/site-packages/aiogram/bot/api.py", line 139, in make_request
    async with session.post(url, data=req, **kwargs) as response:
  File "/home/nizomjon/PycharmProjects/Tiu_bot/.venv/lib/python3.9/site-packages/aiohttp/client.py", line 1167, in __aenter__
    self._resp = await self._coro
  File "/home/nizomjon/PycharmProjects/Tiu_bot/.venv/lib/python3.9/site-packages/aiohttp/client.py", line 562, in _request
    conn = await self._connector.connect(
  File "/home/nizomjon/PycharmProjects/Tiu_bot/.venv/lib/python3.9/site-packages/aiohttp/connector.py", line 540, in connect
    proto = await self._create_connection(req, traces, timeout)
  File "/home/nizomjon/PycharmProjects/Tiu_bot/.venv/lib/python3.9/site-packages/aiohttp/connector.py", line 901, in _create_connection
    _, proto = await self._create_direct_connection(req, traces, timeout)
  File "/home/nizomjon/PycharmProjects/Tiu_bot/.venv/lib/python3.9/site-packages/aiohttp/connector.py", line 1169, in _create_direct_connection
    raise ClientConnectorError(req.connection_key, exc) from exc
aiohttp.client_exceptions.ClientConnectorError: Cannot connect to host api.telegram.org:443 ssl:default [Temporary failure in name resolution]

During handling of the above exception, another exception occurred:

Traceback (most recent call last):
  File "/home/nizomjon/PycharmProjects/Tiu_bot/.venv/lib/python3.9/site-packages/aiogram/dispatcher/dispatcher.py", line 381, in start_polling
    updates = await self.bot.get_updates(
  File "/home/nizomjon/PycharmProjects/Tiu_bot/.venv/lib/python3.9/site-packages/aiogram/bot/bot.py", line 110, in get_updates
    result = await self.request(api.Methods.GET_UPDATES, payload)
  File "/home/nizomjon/PycharmProjects/Tiu_bot/.venv/lib/python3.9/site-packages/aiogram/bot/base.py", line 236, in request
    return await api.make_request(await self.get_session(), self.server, self.__token, method, data, files,
  File "/home/nizomjon/PycharmProjects/Tiu_bot/.venv/lib/python3.9/site-packages/aiogram/bot/api.py", line 142, in make_request
    raise exceptions.NetworkError(f"aiohttp client throws an error: {e.__class__.__name__}: {e}")
aiogram.utils.exceptions.NetworkError: Aiohttp client throws an error: ClientConnectorError: Cannot connect to host api.telegram.org:443 ssl:default [Temporary failure in name resolution]
2025-10-21 00:57:54,348 - aiogram.dispatcher.dispatcher - ERROR - Cause exception while getting updates.
Traceback (most recent call last):
  File "/home/nizomjon/PycharmProjects/Tiu_bot/.venv/lib/python3.9/site-packages/aiohttp/connector.py", line 1155, in _create_direct_connection
    hosts = await asyncio.shield(host_resolved)
  File "/home/nizomjon/PycharmProjects/Tiu_bot/.venv/lib/python3.9/site-packages/aiohttp/connector.py", line 874, in _resolve_host
    addrs = await self._resolver.resolve(host, port, family=self._family)
  File "/home/nizomjon/PycharmProjects/Tiu_bot/.venv/lib/python3.9/site-packages/aiohttp/resolver.py", line 33, in resolve
    infos = await self._loop.getaddrinfo(
  File "/usr/local/lib/python3.9/asyncio/base_events.py", line 856, in getaddrinfo
    return await self.run_in_executor(
  File "/usr/local/lib/python3.9/concurrent/futures/thread.py", line 58, in run
    result = self.fn(*self.args, **self.kwargs)
  File "/usr/local/lib/python3.9/socket.py", line 954, in getaddrinfo
    for res in _socket.getaddrinfo(host, port, family, type, proto, flags):
socket.gaierror: [Errno -3] Temporary failure in name resolution

The above exception was the direct cause of the following exception:

Traceback (most recent call last):
  File "/home/nizomjon/PycharmProjects/Tiu_bot/.venv/lib/python3.9/site-packages/aiogram/bot/api.py", line 139, in make_request
    async with session.post(url, data=req, **kwargs) as response:
  File "/home/nizomjon/PycharmProjects/Tiu_bot/.venv/lib/python3.9/site-packages/aiohttp/client.py", line 1167, in __aenter__
    self._resp = await self._coro
  File "/home/nizomjon/PycharmProjects/Tiu_bot/.venv/lib/python3.9/site-packages/aiohttp/client.py", line 562, in _request
    conn = await self._connector.connect(
  File "/home/nizomjon/PycharmProjects/Tiu_bot/.venv/lib/python3.9/site-packages/aiohttp/connector.py", line 540, in connect
    proto = await self._create_connection(req, traces, timeout)
  File "/home/nizomjon/PycharmProjects/Tiu_bot/.venv/lib/python3.9/site-packages/aiohttp/connector.py", line 901, in _create_connection
    _, proto = await self._create_direct_connection(req, traces, timeout)
  File "/home/nizomjon/PycharmProjects/Tiu_bot/.venv/lib/python3.9/site-packages/aiohttp/connector.py", line 1169, in _create_direct_connection
    raise ClientConnectorError(req.connection_key, exc) from exc
aiohttp.client_exceptions.ClientConnectorError: Cannot connect to host api.telegram.org:443 ssl:default [Temporary failure in name resolution]

During handling of the above exception, another exception occurred:

Traceback (most recent call last):
  File "/home/nizomjon/PycharmProjects/Tiu_bot/.venv/lib/python3.9/site-packages/aiogram/dispatcher/dispatcher.py", line 381, in start_polling
    updates = await self.bot.get_updates(
  File "/home/nizomjon/PycharmProjects/Tiu_bot/.venv/lib/python3.9/site-packages/aiogram/bot/bot.py", line 110, in get_updates
    result = await self.request(api.Methods.GET_UPDATES, payload)
  File "/home/nizomjon/PycharmProjects/Tiu_bot/.venv/lib/python3.9/site-packages/aiogram/bot/base.py", line 236, in request
    return await api.make_request(await self.get_session(), self.server, self.__token, method, data, files,
  File "/home/nizomjon/PycharmProjects/Tiu_bot/.venv/lib/python3.9/site-packages/aiogram/bot/api.py", line 142, in make_request
    raise exceptions.NetworkError(f"aiohttp client throws an error: {e.__class__.__name__}: {e}")
aiogram.utils.exceptions.NetworkError: Aiohttp client throws an error: ClientConnectorError: Cannot connect to host api.telegram.org:443 ssl:default [Temporary failure in name resolution]
2025-10-21 00:57:59,352 - aiogram.dispatcher.dispatcher - ERROR - Cause exception while getting updates.
Traceback (most recent call last):
  File "/home/nizomjon/PycharmProjects/Tiu_bot/.venv/lib/python3.9/site-packages/aiohttp/connector.py", line 1155, in _create_direct_connection
    hosts = await asyncio.shield(host_resolved)
  File "/home/nizomjon/PycharmProjects/Tiu_bot/.venv/lib/python3.9/site-packages/aiohttp/connector.py", line 874, in _resolve_host
    addrs = await self._resolver.resolve(host, port, family=self._family)
  File "/home/nizomjon/PycharmProjects/Tiu_bot/.venv/lib/python3.9/site-packages/aiohttp/resolver.py", line 33, in resolve
    infos = await self._loop.getaddrinfo(
  File "/usr/local/lib/python3.9/asyncio/base_events.py", line 856, in getaddrinfo
    return await self.run_in_executor(
  File "/usr/local/lib/python3.9/concurrent/futures/thread.py", line 58, in run
    result = self.fn(*self.args, **self.kwargs)
  File "/usr/local/lib/python3.9/socket.py", line 954, in getaddrinfo
    for res in _socket.getaddrinfo(host, port, family, type, proto, flags):
socket.gaierror: [Errno -3] Temporary failure in name resolution

The above exception was the direct cause of the following exception:

Traceback (most recent call last):
  File "/home/nizomjon/PycharmProjects/Tiu_bot/.venv/lib/python3.9/site-packages/aiogram/bot/api.py", line 139, in make_request
    async with session.post(url, data=req, **kwargs) as response:
  File "/home/nizomjon/PycharmProjects/Tiu_bot/.venv/lib/python3.9/site-packages/aiohttp/client.py", line 1167, in __aenter__
    self._resp = await self._coro
  File "/home/nizomjon/PycharmProjects/Tiu_bot/.venv/lib/python3.9/site-packages/aiohttp/client.py", line 562, in _request
    conn = await self._connector.connect(
  File "/home/nizomjon/PycharmProjects/Tiu_bot/.venv/lib/python3.9/site-packages/aiohttp/connector.py", line 540, in connect
    proto = await self._create_connection(req, traces, timeout)
  File "/home/nizomjon/PycharmProjects/Tiu_bot/.venv/lib/python3.9/site-packages/aiohttp/connector.py", line 901, in _create_connection
    _, proto = await self._create_direct_connection(req, traces, timeout)
  File "/home/nizomjon/PycharmProjects/Tiu_bot/.venv/lib/python3.9/site-packages/aiohttp/connector.py", line 1169, in _create_direct_connection
    raise ClientConnectorError(req.connection_key, exc) from exc
aiohttp.client_exceptions.ClientConnectorError: Cannot connect to host api.telegram.org:443 ssl:default [Temporary failure in name resolution]

During handling of the above exception, another exception occurred:

Traceback (most recent call last):
  File "/home/nizomjon/PycharmProjects/Tiu_bot/.venv/lib/python3.9/site-packages/aiogram/dispatcher/dispatcher.py", line 381, in start_polling
    updates = await self.bot.get_updates(
  File "/home/nizomjon/PycharmProjects/Tiu_bot/.venv/lib/python3.9/site-packages/aiogram/bot/bot.py", line 110, in get_updates
    result = await self.request(api.Methods.GET_UPDATES, payload)
  File "/home/nizomjon/PycharmProjects/Tiu_bot/.venv/lib/python3.9/site-packages/aiogram/bot/base.py", line 236, in request
    return await api.make_request(await self.get_session(), self.server, self.__token, method, data, files,
  File "/home/nizomjon/PycharmProjects/Tiu_bot/.venv/lib/python3.9/site-packages/aiogram/bot/api.py", line 142, in make_request
    raise exceptions.NetworkError(f"aiohttp client throws an error: {e.__class__.__name__}: {e}")
aiogram.utils.exceptions.NetworkError: Aiohttp client throws an error: ClientConnectorError: Cannot connect to host api.telegram.org:443 ssl:default [Temporary failure in name resolution]
2025-10-21 00:58:04,360 - aiogram.dispatcher.dispatcher - ERROR - Cause exception while getting updates.
Traceback (most recent call last):
  File "/home/nizomjon/PycharmProjects/Tiu_bot/.venv/lib/python3.9/site-packages/aiohttp/connector.py", line 1155, in _create_direct_connection
    hosts = await asyncio.shield(host_resolved)
  File "/home/nizomjon/PycharmProjects/Tiu_bot/.venv/lib/python3.9/site-packages/aiohttp/connector.py", line 874, in _resolve_host
    addrs = await self._resolver.resolve(host, port, family=self._family)
  File "/home/nizomjon/PycharmProjects/Tiu_bot/.venv/lib/python3.9/site-packages/aiohttp/resolver.py", line 33, in resolve
    infos = await self._loop.getaddrinfo(
  File "/usr/local/lib/python3.9/asyncio/base_events.py", line 856, in getaddrinfo
    return await self.run_in_executor(
  File "/usr/local/lib/python3.9/concurrent/futures/thread.py", line 58, in run
    result = self.fn(*self.args, **self.kwargs)
  File "/usr/local/lib/python3.9/socket.py", line 954, in getaddrinfo
    for res in _socket.getaddrinfo(host, port, family, type, proto, flags):
socket.gaierror: [Errno -3] Temporary failure in name resolution

The above exception was the direct cause of the following exception:

Traceback (most recent call last):
  File "/home/nizomjon/PycharmProjects/Tiu_bot/.venv/lib/python3.9/site-packages/aiogram/bot/api.py", line 139, in make_request
    async with session.post(url, data=req, **kwargs) as response:
  File "/home/nizomjon/PycharmProjects/Tiu_bot/.venv/lib/python3.9/site-packages/aiohttp/client.py", line 1167, in __aenter__
    self._resp = await self._coro
  File "/home/nizomjon/PycharmProjects/Tiu_bot/.venv/lib/python3.9/site-packages/aiohttp/client.py", line 562, in _request
    conn = await self._connector.connect(
  File "/home/nizomjon/PycharmProjects/Tiu_bot/.venv/lib/python3.9/site-packages/aiohttp/connector.py", line 540, in connect
    proto = await self._create_connection(req, traces, timeout)
  File "/home/nizomjon/PycharmProjects/Tiu_bot/.venv/lib/python3.9/site-packages/aiohttp/connector.py", line 901, in _create_connection
    _, proto = await self._create_direct_connection(req, traces, timeout)
  File "/home/nizomjon/PycharmProjects/Tiu_bot/.venv/lib/python3.9/site-packages/aiohttp/connector.py", line 1169, in _create_direct_connection
    raise ClientConnectorError(req.connection_key, exc) from exc
aiohttp.client_exceptions.ClientConnectorError: Cannot connect to host api.telegram.org:443 ssl:default [Temporary failure in name resolution]

During handling of the above exception, another exception occurred:

Traceback (most recent call last):
  File "/home/nizomjon/PycharmProjects/Tiu_bot/.venv/lib/python3.9/site-packages/aiogram/dispatcher/dispatcher.py", line 381, in start_polling
    updates = await self.bot.get_updates(
  File "/home/nizomjon/PycharmProjects/Tiu_bot/.venv/lib/python3.9/site-packages/aiogram/bot/bot.py", line 110, in get_updates
    result = await self.request(api.Methods.GET_UPDATES, payload)
  File "/home/nizomjon/PycharmProjects/Tiu_bot/.venv/lib/python3.9/site-packages/aiogram/bot/base.py", line 236, in request
    return await api.make_request(await self.get_session(), self.server, self.__token, method, data, files,
  File "/home/nizomjon/PycharmProjects/Tiu_bot/.venv/lib/python3.9/site-packages/aiogram/bot/api.py", line 142, in make_request
    raise exceptions.NetworkError(f"aiohttp client throws an error: {e.__class__.__name__}: {e}")
aiogram.utils.exceptions.NetworkError: Aiohttp client throws an error: ClientConnectorError: Cannot connect to host api.telegram.org:443 ssl:default [Temporary failure in name resolution]
2025-10-21 00:58:09,366 - aiogram.dispatcher.dispatcher - ERROR - Cause exception while getting updates.
Traceback (most recent call last):
  File "/home/nizomjon/PycharmProjects/Tiu_bot/.venv/lib/python3.9/site-packages/aiohttp/connector.py", line 1155, in _create_direct_connection
    hosts = await asyncio.shield(host_resolved)
  File "/home/nizomjon/PycharmProjects/Tiu_bot/.venv/lib/python3.9/site-packages/aiohttp/connector.py", line 874, in _resolve_host
    addrs = await self._resolver.resolve(host, port, family=self._family)
  File "/home/nizomjon/PycharmProjects/Tiu_bot/.venv/lib/python3.9/site-packages/aiohttp/resolver.py", line 33, in resolve
    infos = await self._loop.getaddrinfo(
  File "/usr/local/lib/python3.9/asyncio/base_events.py", line 856, in getaddrinfo
    return await self.run_in_executor(
  File "/usr/local/lib/python3.9/concurrent/futures/thread.py", line 58, in run
    result = self.fn(*self.args, **self.kwargs)
  File "/usr/local/lib/python3.9/socket.py", line 954, in getaddrinfo
    for res in _socket.getaddrinfo(host, port, family, type, proto, flags):
socket.gaierror: [Errno -3] Temporary failure in name resolution

The above exception was the direct cause of the following exception:

Traceback (most recent call last):
  File "/home/nizomjon/PycharmProjects/Tiu_bot/.venv/lib/python3.9/site-packages/aiogram/bot/api.py", line 139, in make_request
    async with session.post(url, data=req, **kwargs) as response:
  File "/home/nizomjon/PycharmProjects/Tiu_bot/.venv/lib/python3.9/site-packages/aiohttp/client.py", line 1167, in __aenter__
    self._resp = await self._coro
  File "/home/nizomjon/PycharmProjects/Tiu_bot/.venv/lib/python3.9/site-packages/aiohttp/client.py", line 562, in _request
    conn = await self._connector.connect(
  File "/home/nizomjon/PycharmProjects/Tiu_bot/.venv/lib/python3.9/site-packages/aiohttp/connector.py", line 540, in connect
    proto = await self._create_connection(req, traces, timeout)
  File "/home/nizomjon/PycharmProjects/Tiu_bot/.venv/lib/python3.9/site-packages/aiohttp/connector.py", line 901, in _create_connection
    _, proto = await self._create_direct_connection(req, traces, timeout)
  File "/home/nizomjon/PycharmProjects/Tiu_bot/.venv/lib/python3.9/site-packages/aiohttp/connector.py", line 1169, in _create_direct_connection
    raise ClientConnectorError(req.connection_key, exc) from exc
aiohttp.client_exceptions.ClientConnectorError: Cannot connect to host api.telegram.org:443 ssl:default [Temporary failure in name resolution]

During handling of the above exception, another exception occurred:

Traceback (most recent call last):
  File "/home/nizomjon/PycharmProjects/Tiu_bot/.venv/lib/python3.9/site-packages/aiogram/dispatcher/dispatcher.py", line 381, in start_polling
    updates = await self.bot.get_updates(
  File "/home/nizomjon/PycharmProjects/Tiu_bot/.venv/lib/python3.9/site-packages/aiogram/bot/bot.py", line 110, in get_updates
    result = await self.request(api.Methods.GET_UPDATES, payload)
  File "/home/nizomjon/PycharmProjects/Tiu_bot/.venv/lib/python3.9/site-packages/aiogram/bot/base.py", line 236, in request
    return await api.make_request(await self.get_session(), self.server, self.__token, method, data, files,
  File "/home/nizomjon/PycharmProjects/Tiu_bot/.venv/lib/python3.9/site-packages/aiogram/bot/api.py", line 142, in make_request
    raise exceptions.NetworkError(f"aiohttp client throws an error: {e.__class__.__name__}: {e}")
aiogram.utils.exceptions.NetworkError: Aiohttp client throws an error: ClientConnectorError: Cannot connect to host api.telegram.org:443 ssl:default [Temporary failure in name resolution]
2025-10-21 00:58:14,374 - aiogram.dispatcher.dispatcher - ERROR - Cause exception while getting updates.
Traceback (most recent call last):
  File "/home/nizomjon/PycharmProjects/Tiu_bot/.venv/lib/python3.9/site-packages/aiohttp/connector.py", line 1155, in _create_direct_connection
    hosts = await asyncio.shield(host_resolved)
  File "/home/nizomjon/PycharmProjects/Tiu_bot/.venv/lib/python3.9/site-packages/aiohttp/connector.py", line 874, in _resolve_host
    addrs = await self._resolver.resolve(host, port, family=self._family)
  File "/home/nizomjon/PycharmProjects/Tiu_bot/.venv/lib/python3.9/site-packages/aiohttp/resolver.py", line 33, in resolve
    infos = await self._loop.getaddrinfo(
  File "/usr/local/lib/python3.9/asyncio/base_events.py", line 856, in getaddrinfo
    return await self.run_in_executor(
  File "/usr/local/lib/python3.9/concurrent/futures/thread.py", line 58, in run
    result = self.fn(*self.args, **self.kwargs)
  File "/usr/local/lib/python3.9/socket.py", line 954, in getaddrinfo
    for res in _socket.getaddrinfo(host, port, family, type, proto, flags):
socket.gaierror: [Errno -3] Temporary failure in name resolution

The above exception was the direct cause of the following exception:

Traceback (most recent call last):
  File "/home/nizomjon/PycharmProjects/Tiu_bot/.venv/lib/python3.9/site-packages/aiogram/bot/api.py", line 139, in make_request
    async with session.post(url, data=req, **kwargs) as response:
  File "/home/nizomjon/PycharmProjects/Tiu_bot/.venv/lib/python3.9/site-packages/aiohttp/client.py", line 1167, in __aenter__
    self._resp = await self._coro
  File "/home/nizomjon/PycharmProjects/Tiu_bot/.venv/lib/python3.9/site-packages/aiohttp/client.py", line 562, in _request
    conn = await self._connector.connect(
  File "/home/nizomjon/PycharmProjects/Tiu_bot/.venv/lib/python3.9/site-packages/aiohttp/connector.py", line 540, in connect
    proto = await self._create_connection(req, traces, timeout)
  File "/home/nizomjon/PycharmProjects/Tiu_bot/.venv/lib/python3.9/site-packages/aiohttp/connector.py", line 901, in _create_connection
    _, proto = await self._create_direct_connection(req, traces, timeout)
  File "/home/nizomjon/PycharmProjects/Tiu_bot/.venv/lib/python3.9/site-packages/aiohttp/connector.py", line 1169, in _create_direct_connection
    raise ClientConnectorError(req.connection_key, exc) from exc
aiohttp.client_exceptions.ClientConnectorError: Cannot connect to host api.telegram.org:443 ssl:default [Temporary failure in name resolution]

During handling of the above exception, another exception occurred:

Traceback (most recent call last):
  File "/home/nizomjon/PycharmProjects/Tiu_bot/.venv/lib/python3.9/site-packages/aiogram/dispatcher/dispatcher.py", line 381, in start_polling
    updates = await self.bot.get_updates(
  File "/home/nizomjon/PycharmProjects/Tiu_bot/.venv/lib/python3.9/site-packages/aiogram/bot/bot.py", line 110, in get_updates
    result = await self.request(api.Methods.GET_UPDATES, payload)
  File "/home/nizomjon/PycharmProjects/Tiu_bot/.venv/lib/python3.9/site-packages/aiogram/bot/base.py", line 236, in request
    return await api.make_request(await self.get_session(), self.server, self.__token, method, data, files,
  File "/home/nizomjon/PycharmProjects/Tiu_bot/.venv/lib/python3.9/site-packages/aiogram/bot/api.py", line 142, in make_request
    raise exceptions.NetworkError(f"aiohttp client throws an error: {e.__class__.__name__}: {e}")
aiogram.utils.exceptions.NetworkError: Aiohttp client throws an error: ClientConnectorError: Cannot connect to host api.telegram.org:443 ssl:default [Temporary failure in name resolution]
2025-10-21 00:58:19,380 - aiogram.dispatcher.dispatcher - ERROR - Cause exception while getting updates.
Traceback (most recent call last):
  File "/home/nizomjon/PycharmProjects/Tiu_bot/.venv/lib/python3.9/site-packages/aiohttp/connector.py", line 1155, in _create_direct_connection
    hosts = await asyncio.shield(host_resolved)
  File "/home/nizomjon/PycharmProjects/Tiu_bot/.venv/lib/python3.9/site-packages/aiohttp/connector.py", line 874, in _resolve_host
    addrs = await self._resolver.resolve(host, port, family=self._family)
  File "/home/nizomjon/PycharmProjects/Tiu_bot/.venv/lib/python3.9/site-packages/aiohttp/resolver.py", line 33, in resolve
    infos = await self._loop.getaddrinfo(
  File "/usr/local/lib/python3.9/asyncio/base_events.py", line 856, in getaddrinfo
    return await self.run_in_executor(
  File "/usr/local/lib/python3.9/concurrent/futures/thread.py", line 58, in run
    result = self.fn(*self.args, **self.kwargs)
  File "/usr/local/lib/python3.9/socket.py", line 954, in getaddrinfo
    for res in _socket.getaddrinfo(host, port, family, type, proto, flags):
socket.gaierror: [Errno -3] Temporary failure in name resolution

The above exception was the direct cause of the following exception:

Traceback (most recent call last):
  File "/home/nizomjon/PycharmProjects/Tiu_bot/.venv/lib/python3.9/site-packages/aiogram/bot/api.py", line 139, in make_request
    async with session.post(url, data=req, **kwargs) as response:
  File "/home/nizomjon/PycharmProjects/Tiu_bot/.venv/lib/python3.9/site-packages/aiohttp/client.py", line 1167, in __aenter__
    self._resp = await self._coro
  File "/home/nizomjon/PycharmProjects/Tiu_bot/.venv/lib/python3.9/site-packages/aiohttp/client.py", line 562, in _request
    conn = await self._connector.connect(
  File "/home/nizomjon/PycharmProjects/Tiu_bot/.venv/lib/python3.9/site-packages/aiohttp/connector.py", line 540, in connect
    proto = await self._create_connection(req, traces, timeout)
  File "/home/nizomjon/PycharmProjects/Tiu_bot/.venv/lib/python3.9/site-packages/aiohttp/connector.py", line 901, in _create_connection
    _, proto = await self._create_direct_connection(req, traces, timeout)
  File "/home/nizomjon/PycharmProjects/Tiu_bot/.venv/lib/python3.9/site-packages/aiohttp/connector.py", line 1169, in _create_direct_connection
    raise ClientConnectorError(req.connection_key, exc) from exc
aiohttp.client_exceptions.ClientConnectorError: Cannot connect to host api.telegram.org:443 ssl:default [Temporary failure in name resolution]

During handling of the above exception, another exception occurred:

Traceback (most recent call last):
  File "/home/nizomjon/PycharmProjects/Tiu_bot/.venv/lib/python3.9/site-packages/aiogram/dispatcher/dispatcher.py", line 381, in start_polling
    updates = await self.bot.get_updates(
  File "/home/nizomjon/PycharmProjects/Tiu_bot/.venv/lib/python3.9/site-packages/aiogram/bot/bot.py", line 110, in get_updates
    result = await self.request(api.Methods.GET_UPDATES, payload)
  File "/home/nizomjon/PycharmProjects/Tiu_bot/.venv/lib/python3.9/site-packages/aiogram/bot/base.py", line 236, in request
    return await api.make_request(await self.get_session(), self.server, self.__token, method, data, files,
  File "/home/nizomjon/PycharmProjects/Tiu_bot/.venv/lib/python3.9/site-packages/aiogram/bot/api.py", line 142, in make_request
    raise exceptions.NetworkError(f"aiohttp client throws an error: {e.__class__.__name__}: {e}")
aiogram.utils.exceptions.NetworkError: Aiohttp client throws an error: ClientConnectorError: Cannot connect to host api.telegram.org:443 ssl:default [Temporary failure in name resolution]
2025-10-21 00:58:24,385 - aiogram.dispatcher.dispatcher - ERROR - Cause exception while getting updates.
Traceback (most recent call last):
  File "/home/nizomjon/PycharmProjects/Tiu_bot/.venv/lib/python3.9/site-packages/aiohttp/connector.py", line 1155, in _create_direct_connection
    hosts = await asyncio.shield(host_resolved)
  File "/home/nizomjon/PycharmProjects/Tiu_bot/.venv/lib/python3.9/site-packages/aiohttp/connector.py", line 874, in _resolve_host
    addrs = await self._resolver.resolve(host, port, family=self._family)
  File "/home/nizomjon/PycharmProjects/Tiu_bot/.venv/lib/python3.9/site-packages/aiohttp/resolver.py", line 33, in resolve
    infos = await self._loop.getaddrinfo(
  File "/usr/local/lib/python3.9/asyncio/base_events.py", line 856, in getaddrinfo
    return await self.run_in_executor(
  File "/usr/local/lib/python3.9/concurrent/futures/thread.py", line 58, in run
    result = self.fn(*self.args, **self.kwargs)
  File "/usr/local/lib/python3.9/socket.py", line 954, in getaddrinfo
    for res in _socket.getaddrinfo(host, port, family, type, proto, flags):
socket.gaierror: [Errno -3] Temporary failure in name resolution

The above exception was the direct cause of the following exception:

Traceback (most recent call last):
  File "/home/nizomjon/PycharmProjects/Tiu_bot/.venv/lib/python3.9/site-packages/aiogram/bot/api.py", line 139, in make_request
    async with session.post(url, data=req, **kwargs) as response:
  File "/home/nizomjon/PycharmProjects/Tiu_bot/.venv/lib/python3.9/site-packages/aiohttp/client.py", line 1167, in __aenter__
    self._resp = await self._coro
  File "/home/nizomjon/PycharmProjects/Tiu_bot/.venv/lib/python3.9/site-packages/aiohttp/client.py", line 562, in _request
    conn = await self._connector.connect(
  File "/home/nizomjon/PycharmProjects/Tiu_bot/.venv/lib/python3.9/site-packages/aiohttp/connector.py", line 540, in connect
    proto = await self._create_connection(req, traces, timeout)
  File "/home/nizomjon/PycharmProjects/Tiu_bot/.venv/lib/python3.9/site-packages/aiohttp/connector.py", line 901, in _create_connection
    _, proto = await self._create_direct_connection(req, traces, timeout)
  File "/home/nizomjon/PycharmProjects/Tiu_bot/.venv/lib/python3.9/site-packages/aiohttp/connector.py", line 1169, in _create_direct_connection
    raise ClientConnectorError(req.connection_key, exc) from exc
aiohttp.client_exceptions.ClientConnectorError: Cannot connect to host api.telegram.org:443 ssl:default [Temporary failure in name resolution]

During handling of the above exception, another exception occurred:

Traceback (most recent call last):
  File "/home/nizomjon/PycharmProjects/Tiu_bot/.venv/lib/python3.9/site-packages/aiogram/dispatcher/dispatcher.py", line 381, in start_polling
    updates = await self.bot.get_updates(
  File "/home/nizomjon/PycharmProjects/Tiu_bot/.venv/lib/python3.9/site-packages/aiogram/bot/bot.py", line 110, in get_updates
    result = await self.request(api.Methods.GET_UPDATES, payload)
  File "/home/nizomjon/PycharmProjects/Tiu_bot/.venv/lib/python3.9/site-packages/aiogram/bot/base.py", line 236, in request
    return await api.make_request(await self.get_session(), self.server, self.__token, method, data, files,
  File "/home/nizomjon/PycharmProjects/Tiu_bot/.venv/lib/python3.9/site-packages/aiogram/bot/api.py", line 142, in make_request
    raise exceptions.NetworkError(f"aiohttp client throws an error: {e.__class__.__name__}: {e}")
aiogram.utils.exceptions.NetworkError: Aiohttp client throws an error: ClientConnectorError: Cannot connect to host api.telegram.org:443 ssl:default [Temporary failure in name resolution]
2025-10-21 00:58:29,392 - aiogram.dispatcher.dispatcher - ERROR - Cause exception while getting updates.
Traceback (most recent call last):
  File "/home/nizomjon/PycharmProjects/Tiu_bot/.venv/lib/python3.9/site-packages/aiohttp/connector.py", line 1155, in _create_direct_connection
    hosts = await asyncio.shield(host_resolved)
  File "/home/nizomjon/PycharmProjects/Tiu_bot/.venv/lib/python3.9/site-packages/aiohttp/connector.py", line 874, in _resolve_host
    addrs = await self._resolver.resolve(host, port, family=self._family)
  File "/home/nizomjon/PycharmProjects/Tiu_bot/.venv/lib/python3.9/site-packages/aiohttp/resolver.py", line 33, in resolve
    infos = await self._loop.getaddrinfo(
  File "/usr/local/lib/python3.9/asyncio/base_events.py", line 856, in getaddrinfo
    return await self.run_in_executor(
  File "/usr/local/lib/python3.9/concurrent/futures/thread.py", line 58, in run
    result = self.fn(*self.args, **self.kwargs)
  File "/usr/local/lib/python3.9/socket.py", line 954, in getaddrinfo
    for res in _socket.getaddrinfo(host, port, family, type, proto, flags):
socket.gaierror: [Errno -3] Temporary failure in name resolution

The above exception was the direct cause of the following exception:

Traceback (most recent call last):
  File "/home/nizomjon/PycharmProjects/Tiu_bot/.venv/lib/python3.9/site-packages/aiogram/bot/api.py", line 139, in make_request
    async with session.post(url, data=req, **kwargs) as response:
  File "/home/nizomjon/PycharmProjects/Tiu_bot/.venv/lib/python3.9/site-packages/aiohttp/client.py", line 1167, in __aenter__
    self._resp = await self._coro
  File "/home/nizomjon/PycharmProjects/Tiu_bot/.venv/lib/python3.9/site-packages/aiohttp/client.py", line 562, in _request
    conn = await self._connector.connect(
  File "/home/nizomjon/PycharmProjects/Tiu_bot/.venv/lib/python3.9/site-packages/aiohttp/connector.py", line 540, in connect
    proto = await self._create_connection(req, traces, timeout)
  File "/home/nizomjon/PycharmProjects/Tiu_bot/.venv/lib/python3.9/site-packages/aiohttp/connector.py", line 901, in _create_connection
    _, proto = await self._create_direct_connection(req, traces, timeout)
  File "/home/nizomjon/PycharmProjects/Tiu_bot/.venv/lib/python3.9/site-packages/aiohttp/connector.py", line 1169, in _create_direct_connection
    raise ClientConnectorError(req.connection_key, exc) from exc
aiohttp.client_exceptions.ClientConnectorError: Cannot connect to host api.telegram.org:443 ssl:default [Temporary failure in name resolution]

During handling of the above exception, another exception occurred:

Traceback (most recent call last):
  File "/home/nizomjon/PycharmProjects/Tiu_bot/.venv/lib/python3.9/site-packages/aiogram/dispatcher/dispatcher.py", line 381, in start_polling
    updates = await self.bot.get_updates(
  File "/home/nizomjon/PycharmProjects/Tiu_bot/.venv/lib/python3.9/site-packages/aiogram/bot/bot.py", line 110, in get_updates
    result = await self.request(api.Methods.GET_UPDATES, payload)
  File "/home/nizomjon/PycharmProjects/Tiu_bot/.venv/lib/python3.9/site-packages/aiogram/bot/base.py", line 236, in request
    return await api.make_request(await self.get_session(), self.server, self.__token, method, data, files,
  File "/home/nizomjon/PycharmProjects/Tiu_bot/.venv/lib/python3.9/site-packages/aiogram/bot/api.py", line 142, in make_request
    raise exceptions.NetworkError(f"aiohttp client throws an error: {e.__class__.__name__}: {e}")
aiogram.utils.exceptions.NetworkError: Aiohttp client throws an error: ClientConnectorError: Cannot connect to host api.telegram.org:443 ssl:default [Temporary failure in name resolution]
2025-10-21 00:58:34,396 - aiogram.dispatcher.dispatcher - ERROR - Cause exception while getting updates.
Traceback (most recent call last):
  File "/home/nizomjon/PycharmProjects/Tiu_bot/.venv/lib/python3.9/site-packages/aiohttp/connector.py", line 1155, in _create_direct_connection
    hosts = await asyncio.shield(host_resolved)
  File "/home/nizomjon/PycharmProjects/Tiu_bot/.venv/lib/python3.9/site-packages/aiohttp/connector.py", line 874, in _resolve_host
    addrs = await self._resolver.resolve(host, port, family=self._family)
  File "/home/nizomjon/PycharmProjects/Tiu_bot/.venv/lib/python3.9/site-packages/aiohttp/resolver.py", line 33, in resolve
    infos = await self._loop.getaddrinfo(
  File "/usr/local/lib/python3.9/asyncio/base_events.py", line 856, in getaddrinfo
    return await self.run_in_executor(
  File "/usr/local/lib/python3.9/concurrent/futures/thread.py", line 58, in run
    result = self.fn(*self.args, **self.kwargs)
  File "/usr/local/lib/python3.9/socket.py", line 954, in getaddrinfo
    for res in _socket.getaddrinfo(host, port, family, type, proto, flags):
socket.gaierror: [Errno -3] Temporary failure in name resolution

The above exception was the direct cause of the following exception:

Traceback (most recent call last):
  File "/home/nizomjon/PycharmProjects/Tiu_bot/.venv/lib/python3.9/site-packages/aiogram/bot/api.py", line 139, in make_request
    async with session.post(url, data=req, **kwargs) as response:
  File "/home/nizomjon/PycharmProjects/Tiu_bot/.venv/lib/python3.9/site-packages/aiohttp/client.py", line 1167, in __aenter__
    self._resp = await self._coro
  File "/home/nizomjon/PycharmProjects/Tiu_bot/.venv/lib/python3.9/site-packages/aiohttp/client.py", line 562, in _request
    conn = await self._connector.connect(
  File "/home/nizomjon/PycharmProjects/Tiu_bot/.venv/lib/python3.9/site-packages/aiohttp/connector.py", line 540, in connect
    proto = await self._create_connection(req, traces, timeout)
  File "/home/nizomjon/PycharmProjects/Tiu_bot/.venv/lib/python3.9/site-packages/aiohttp/connector.py", line 901, in _create_connection
    _, proto = await self._create_direct_connection(req, traces, timeout)
  File "/home/nizomjon/PycharmProjects/Tiu_bot/.venv/lib/python3.9/site-packages/aiohttp/connector.py", line 1169, in _create_direct_connection
    raise ClientConnectorError(req.connection_key, exc) from exc
aiohttp.client_exceptions.ClientConnectorError: Cannot connect to host api.telegram.org:443 ssl:default [Temporary failure in name resolution]

During handling of the above exception, another exception occurred:

Traceback (most recent call last):
  File "/home/nizomjon/PycharmProjects/Tiu_bot/.venv/lib/python3.9/site-packages/aiogram/dispatcher/dispatcher.py", line 381, in start_polling
    updates = await self.bot.get_updates(
  File "/home/nizomjon/PycharmProjects/Tiu_bot/.venv/lib/python3.9/site-packages/aiogram/bot/bot.py", line 110, in get_updates
    result = await self.request(api.Methods.GET_UPDATES, payload)
  File "/home/nizomjon/PycharmProjects/Tiu_bot/.venv/lib/python3.9/site-packages/aiogram/bot/base.py", line 236, in request
    return await api.make_request(await self.get_session(), self.server, self.__token, method, data, files,
  File "/home/nizomjon/PycharmProjects/Tiu_bot/.venv/lib/python3.9/site-packages/aiogram/bot/api.py", line 142, in make_request
    raise exceptions.NetworkError(f"aiohttp client throws an error: {e.__class__.__name__}: {e}")
aiogram.utils.exceptions.NetworkError: Aiohttp client throws an error: ClientConnectorError: Cannot connect to host api.telegram.org:443 ssl:default [Temporary failure in name resolution]
2025-10-21 00:58:39,405 - aiogram.dispatcher.dispatcher - ERROR - Cause exception while getting updates.
Traceback (most recent call last):
  File "/home/nizomjon/PycharmProjects/Tiu_bot/.venv/lib/python3.9/site-packages/aiohttp/connector.py", line 1155, in _create_direct_connection
    hosts = await asyncio.shield(host_resolved)
  File "/home/nizomjon/PycharmProjects/Tiu_bot/.venv/lib/python3.9/site-packages/aiohttp/connector.py", line 874, in _resolve_host
    addrs = await self._resolver.resolve(host, port, family=self._family)
  File "/home/nizomjon/PycharmProjects/Tiu_bot/.venv/lib/python3.9/site-packages/aiohttp/resolver.py", line 33, in resolve
    infos = await self._loop.getaddrinfo(
  File "/usr/local/lib/python3.9/asyncio/base_events.py", line 856, in getaddrinfo
    return await self.run_in_executor(
  File "/usr/local/lib/python3.9/concurrent/futures/thread.py", line 58, in run
    result = self.fn(*self.args, **self.kwargs)
  File "/usr/local/lib/python3.9/socket.py", line 954, in getaddrinfo
    for res in _socket.getaddrinfo(host, port, family, type, proto, flags):
socket.gaierror: [Errno -3] Temporary failure in name resolution

The above exception was the direct cause of the following exception:

Traceback (most recent call last):
  File "/home/nizomjon/PycharmProjects/Tiu_bot/.venv/lib/python3.9/site-packages/aiogram/bot/api.py", line 139, in make_request
    async with session.post(url, data=req, **kwargs) as response:
  File "/home/nizomjon/PycharmProjects/Tiu_bot/.venv/lib/python3.9/site-packages/aiohttp/client.py", line 1167, in __aenter__
    self._resp = await self._coro
  File "/home/nizomjon/PycharmProjects/Tiu_bot/.venv/lib/python3.9/site-packages/aiohttp/client.py", line 562, in _request
    conn = await self._connector.connect(
  File "/home/nizomjon/PycharmProjects/Tiu_bot/.venv/lib/python3.9/site-packages/aiohttp/connector.py", line 540, in connect
    proto = await self._create_connection(req, traces, timeout)
  File "/home/nizomjon/PycharmProjects/Tiu_bot/.venv/lib/python3.9/site-packages/aiohttp/connector.py", line 901, in _create_connection
    _, proto = await self._create_direct_connection(req, traces, timeout)
  File "/home/nizomjon/PycharmProjects/Tiu_bot/.venv/lib/python3.9/site-packages/aiohttp/connector.py", line 1169, in _create_direct_connection
    raise ClientConnectorError(req.connection_key, exc) from exc
aiohttp.client_exceptions.ClientConnectorError: Cannot connect to host api.telegram.org:443 ssl:default [Temporary failure in name resolution]

During handling of the above exception, another exception occurred:

Traceback (most recent call last):
  File "/home/nizomjon/PycharmProjects/Tiu_bot/.venv/lib/python3.9/site-packages/aiogram/dispatcher/dispatcher.py", line 381, in start_polling
    updates = await self.bot.get_updates(
  File "/home/nizomjon/PycharmProjects/Tiu_bot/.venv/lib/python3.9/site-packages/aiogram/bot/bot.py", line 110, in get_updates
    result = await self.request(api.Methods.GET_UPDATES, payload)
  File "/home/nizomjon/PycharmProjects/Tiu_bot/.venv/lib/python3.9/site-packages/aiogram/bot/base.py", line 236, in request
    return await api.make_request(await self.get_session(), self.server, self.__token, method, data, files,
  File "/home/nizomjon/PycharmProjects/Tiu_bot/.venv/lib/python3.9/site-packages/aiogram/bot/api.py", line 142, in make_request
    raise exceptions.NetworkError(f"aiohttp client throws an error: {e.__class__.__name__}: {e}")
aiogram.utils.exceptions.NetworkError: Aiohttp client throws an error: ClientConnectorError: Cannot connect to host api.telegram.org:443 ssl:default [Temporary failure in name resolution]
2025-10-21 00:58:44,413 - aiogram.dispatcher.dispatcher - ERROR - Cause exception while getting updates.
Traceback (most recent call last):
  File "/home/nizomjon/PycharmProjects/Tiu_bot/.venv/lib/python3.9/site-packages/aiohttp/connector.py", line 1155, in _create_direct_connection
    hosts = await asyncio.shield(host_resolved)
  File "/home/nizomjon/PycharmProjects/Tiu_bot/.venv/lib/python3.9/site-packages/aiohttp/connector.py", line 874, in _resolve_host
    addrs = await self._resolver.resolve(host, port, family=self._family)
  File "/home/nizomjon/PycharmProjects/Tiu_bot/.venv/lib/python3.9/site-packages/aiohttp/resolver.py", line 33, in resolve
    infos = await self._loop.getaddrinfo(
  File "/usr/local/lib/python3.9/asyncio/base_events.py", line 856, in getaddrinfo
    return await self.run_in_executor(
  File "/usr/local/lib/python3.9/concurrent/futures/thread.py", line 58, in run
    result = self.fn(*self.args, **self.kwargs)
  File "/usr/local/lib/python3.9/socket.py", line 954, in getaddrinfo
    for res in _socket.getaddrinfo(host, port, family, type, proto, flags):
socket.gaierror: [Errno -3] Temporary failure in name resolution

The above exception was the direct cause of the following exception:

Traceback (most recent call last):
  File "/home/nizomjon/PycharmProjects/Tiu_bot/.venv/lib/python3.9/site-packages/aiogram/bot/api.py", line 139, in make_request
    async with session.post(url, data=req, **kwargs) as response:
  File "/home/nizomjon/PycharmProjects/Tiu_bot/.venv/lib/python3.9/site-packages/aiohttp/client.py", line 1167, in __aenter__
    self._resp = await self._coro
  File "/home/nizomjon/PycharmProjects/Tiu_bot/.venv/lib/python3.9/site-packages/aiohttp/client.py", line 562, in _request
    conn = await self._connector.connect(
  File "/home/nizomjon/PycharmProjects/Tiu_bot/.venv/lib/python3.9/site-packages/aiohttp/connector.py", line 540, in connect
    proto = await self._create_connection(req, traces, timeout)
  File "/home/nizomjon/PycharmProjects/Tiu_bot/.venv/lib/python3.9/site-packages/aiohttp/connector.py", line 901, in _create_connection
    _, proto = await self._create_direct_connection(req, traces, timeout)
  File "/home/nizomjon/PycharmProjects/Tiu_bot/.venv/lib/python3.9/site-packages/aiohttp/connector.py", line 1169, in _create_direct_connection
    raise ClientConnectorError(req.connection_key, exc) from exc
aiohttp.client_exceptions.ClientConnectorError: Cannot connect to host api.telegram.org:443 ssl:default [Temporary failure in name resolution]

During handling of the above exception, another exception occurred:

Traceback (most recent call last):
  File "/home/nizomjon/PycharmProjects/Tiu_bot/.venv/lib/python3.9/site-packages/aiogram/dispatcher/dispatcher.py", line 381, in start_polling
    updates = await self.bot.get_updates(
  File "/home/nizomjon/PycharmProjects/Tiu_bot/.venv/lib/python3.9/site-packages/aiogram/bot/bot.py", line 110, in get_updates
    result = await self.request(api.Methods.GET_UPDATES, payload)
  File "/home/nizomjon/PycharmProjects/Tiu_bot/.venv/lib/python3.9/site-packages/aiogram/bot/base.py", line 236, in request
    return await api.make_request(await self.get_session(), self.server, self.__token, method, data, files,
  File "/home/nizomjon/PycharmProjects/Tiu_bot/.venv/lib/python3.9/site-packages/aiogram/bot/api.py", line 142, in make_request
    raise exceptions.NetworkError(f"aiohttp client throws an error: {e.__class__.__name__}: {e}")
aiogram.utils.exceptions.NetworkError: Aiohttp client throws an error: ClientConnectorError: Cannot connect to host api.telegram.org:443 ssl:default [Temporary failure in name resolution]
2025-10-21 00:58:49,421 - aiogram.dispatcher.dispatcher - ERROR - Cause exception while getting updates.
Traceback (most recent call last):
  File "/home/nizomjon/PycharmProjects/Tiu_bot/.venv/lib/python3.9/site-packages/aiohttp/connector.py", line 1155, in _create_direct_connection
    hosts = await asyncio.shield(host_resolved)
  File "/home/nizomjon/PycharmProjects/Tiu_bot/.venv/lib/python3.9/site-packages/aiohttp/connector.py", line 874, in _resolve_host
    addrs = await self._resolver.resolve(host, port, family=self._family)
  File "/home/nizomjon/PycharmProjects/Tiu_bot/.venv/lib/python3.9/site-packages/aiohttp/resolver.py", line 33, in resolve
    infos = await self._loop.getaddrinfo(
  File "/usr/local/lib/python3.9/asyncio/base_events.py", line 856, in getaddrinfo
    return await self.run_in_executor(
  File "/usr/local/lib/python3.9/concurrent/futures/thread.py", line 58, in run
    result = self.fn(*self.args, **self.kwargs)
  File "/usr/local/lib/python3.9/socket.py", line 954, in getaddrinfo
    for res in _socket.getaddrinfo(host, port, family, type, proto, flags):
socket.gaierror: [Errno -3] Temporary failure in name resolution

The above exception was the direct cause of the following exception:

Traceback (most recent call last):
  File "/home/nizomjon/PycharmProjects/Tiu_bot/.venv/lib/python3.9/site-packages/aiogram/bot/api.py", line 139, in make_request
    async with session.post(url, data=req, **kwargs) as response:
  File "/home/nizomjon/PycharmProjects/Tiu_bot/.venv/lib/python3.9/site-packages/aiohttp/client.py", line 1167, in __aenter__
    self._resp = await self._coro
  File "/home/nizomjon/PycharmProjects/Tiu_bot/.venv/lib/python3.9/site-packages/aiohttp/client.py", line 562, in _request
    conn = await self._connector.connect(
  File "/home/nizomjon/PycharmProjects/Tiu_bot/.venv/lib/python3.9/site-packages/aiohttp/connector.py", line 540, in connect
    proto = await self._create_connection(req, traces, timeout)
  File "/home/nizomjon/PycharmProjects/Tiu_bot/.venv/lib/python3.9/site-packages/aiohttp/connector.py", line 901, in _create_connection
    _, proto = await self._create_direct_connection(req, traces, timeout)
  File "/home/nizomjon/PycharmProjects/Tiu_bot/.venv/lib/python3.9/site-packages/aiohttp/connector.py", line 1169, in _create_direct_connection
    raise ClientConnectorError(req.connection_key, exc) from exc
aiohttp.client_exceptions.ClientConnectorError: Cannot connect to host api.telegram.org:443 ssl:default [Temporary failure in name resolution]

During handling of the above exception, another exception occurred:

Traceback (most recent call last):
  File "/home/nizomjon/PycharmProjects/Tiu_bot/.venv/lib/python3.9/site-packages/aiogram/dispatcher/dispatcher.py", line 381, in start_polling
    updates = await self.bot.get_updates(
  File "/home/nizomjon/PycharmProjects/Tiu_bot/.venv/lib/python3.9/site-packages/aiogram/bot/bot.py", line 110, in get_updates
    result = await self.request(api.Methods.GET_UPDATES, payload)
  File "/home/nizomjon/PycharmProjects/Tiu_bot/.venv/lib/python3.9/site-packages/aiogram/bot/base.py", line 236, in request
    return await api.make_request(await self.get_session(), self.server, self.__token, method, data, files,
  File "/home/nizomjon/PycharmProjects/Tiu_bot/.venv/lib/python3.9/site-packages/aiogram/bot/api.py", line 142, in make_request
    raise exceptions.NetworkError(f"aiohttp client throws an error: {e.__class__.__name__}: {e}")
aiogram.utils.exceptions.NetworkError: Aiohttp client throws an error: ClientConnectorError: Cannot connect to host api.telegram.org:443 ssl:default [Temporary failure in name resolution]
2025-10-21 00:58:54,429 - aiogram.dispatcher.dispatcher - ERROR - Cause exception while getting updates.
Traceback (most recent call last):
  File "/home/nizomjon/PycharmProjects/Tiu_bot/.venv/lib/python3.9/site-packages/aiohttp/connector.py", line 1155, in _create_direct_connection
    hosts = await asyncio.shield(host_resolved)
  File "/home/nizomjon/PycharmProjects/Tiu_bot/.venv/lib/python3.9/site-packages/aiohttp/connector.py", line 874, in _resolve_host
    addrs = await self._resolver.resolve(host, port, family=self._family)
  File "/home/nizomjon/PycharmProjects/Tiu_bot/.venv/lib/python3.9/site-packages/aiohttp/resolver.py", line 33, in resolve
    infos = await self._loop.getaddrinfo(
  File "/usr/local/lib/python3.9/asyncio/base_events.py", line 856, in getaddrinfo
    return await self.run_in_executor(
  File "/usr/local/lib/python3.9/concurrent/futures/thread.py", line 58, in run
    result = self.fn(*self.args, **self.kwargs)
  File "/usr/local/lib/python3.9/socket.py", line 954, in getaddrinfo
    for res in _socket.getaddrinfo(host, port, family, type, proto, flags):
socket.gaierror: [Errno -3] Temporary failure in name resolution

The above exception was the direct cause of the following exception:

Traceback (most recent call last):
  File "/home/nizomjon/PycharmProjects/Tiu_bot/.venv/lib/python3.9/site-packages/aiogram/bot/api.py", line 139, in make_request
    async with session.post(url, data=req, **kwargs) as response:
  File "/home/nizomjon/PycharmProjects/Tiu_bot/.venv/lib/python3.9/site-packages/aiohttp/client.py", line 1167, in __aenter__
    self._resp = await self._coro
  File "/home/nizomjon/PycharmProjects/Tiu_bot/.venv/lib/python3.9/site-packages/aiohttp/client.py", line 562, in _request
    conn = await self._connector.connect(
  File "/home/nizomjon/PycharmProjects/Tiu_bot/.venv/lib/python3.9/site-packages/aiohttp/connector.py", line 540, in connect
    proto = await self._create_connection(req, traces, timeout)
  File "/home/nizomjon/PycharmProjects/Tiu_bot/.venv/lib/python3.9/site-packages/aiohttp/connector.py", line 901, in _create_connection
    _, proto = await self._create_direct_connection(req, traces, timeout)
  File "/home/nizomjon/PycharmProjects/Tiu_bot/.venv/lib/python3.9/site-packages/aiohttp/connector.py", line 1169, in _create_direct_connection
    raise ClientConnectorError(req.connection_key, exc) from exc
aiohttp.client_exceptions.ClientConnectorError: Cannot connect to host api.telegram.org:443 ssl:default [Temporary failure in name resolution]

During handling of the above exception, another exception occurred:

Traceback (most recent call last):
  File "/home/nizomjon/PycharmProjects/Tiu_bot/.venv/lib/python3.9/site-packages/aiogram/dispatcher/dispatcher.py", line 381, in start_polling
    updates = await self.bot.get_updates(
  File "/home/nizomjon/PycharmProjects/Tiu_bot/.venv/lib/python3.9/site-packages/aiogram/bot/bot.py", line 110, in get_updates
    result = await self.request(api.Methods.GET_UPDATES, payload)
  File "/home/nizomjon/PycharmProjects/Tiu_bot/.venv/lib/python3.9/site-packages/aiogram/bot/base.py", line 236, in request
    return await api.make_request(await self.get_session(), self.server, self.__token, method, data, files,
  File "/home/nizomjon/PycharmProjects/Tiu_bot/.venv/lib/python3.9/site-packages/aiogram/bot/api.py", line 142, in make_request
    raise exceptions.NetworkError(f"aiohttp client throws an error: {e.__class__.__name__}: {e}")
aiogram.utils.exceptions.NetworkError: Aiohttp client throws an error: ClientConnectorError: Cannot connect to host api.telegram.org:443 ssl:default [Temporary failure in name resolution]
2025-10-21 00:58:59,436 - aiogram.dispatcher.dispatcher - ERROR - Cause exception while getting updates.
Traceback (most recent call last):
  File "/home/nizomjon/PycharmProjects/Tiu_bot/.venv/lib/python3.9/site-packages/aiohttp/connector.py", line 1155, in _create_direct_connection
    hosts = await asyncio.shield(host_resolved)
  File "/home/nizomjon/PycharmProjects/Tiu_bot/.venv/lib/python3.9/site-packages/aiohttp/connector.py", line 874, in _resolve_host
    addrs = await self._resolver.resolve(host, port, family=self._family)
  File "/home/nizomjon/PycharmProjects/Tiu_bot/.venv/lib/python3.9/site-packages/aiohttp/resolver.py", line 33, in resolve
    infos = await self._loop.getaddrinfo(
  File "/usr/local/lib/python3.9/asyncio/base_events.py", line 856, in getaddrinfo
    return await self.run_in_executor(
  File "/usr/local/lib/python3.9/concurrent/futures/thread.py", line 58, in run
    result = self.fn(*self.args, **self.kwargs)
  File "/usr/local/lib/python3.9/socket.py", line 954, in getaddrinfo
    for res in _socket.getaddrinfo(host, port, family, type, proto, flags):
socket.gaierror: [Errno -3] Temporary failure in name resolution

The above exception was the direct cause of the following exception:

Traceback (most recent call last):
  File "/home/nizomjon/PycharmProjects/Tiu_bot/.venv/lib/python3.9/site-packages/aiogram/bot/api.py", line 139, in make_request
    async with session.post(url, data=req, **kwargs) as response:
  File "/home/nizomjon/PycharmProjects/Tiu_bot/.venv/lib/python3.9/site-packages/aiohttp/client.py", line 1167, in __aenter__
    self._resp = await self._coro
  File "/home/nizomjon/PycharmProjects/Tiu_bot/.venv/lib/python3.9/site-packages/aiohttp/client.py", line 562, in _request
    conn = await self._connector.connect(
  File "/home/nizomjon/PycharmProjects/Tiu_bot/.venv/lib/python3.9/site-packages/aiohttp/connector.py", line 540, in connect
    proto = await self._create_connection(req, traces, timeout)
  File "/home/nizomjon/PycharmProjects/Tiu_bot/.venv/lib/python3.9/site-packages/aiohttp/connector.py", line 901, in _create_connection
    _, proto = await self._create_direct_connection(req, traces, timeout)
  File "/home/nizomjon/PycharmProjects/Tiu_bot/.venv/lib/python3.9/site-packages/aiohttp/connector.py", line 1169, in _create_direct_connection
    raise ClientConnectorError(req.connection_key, exc) from exc
aiohttp.client_exceptions.ClientConnectorError: Cannot connect to host api.telegram.org:443 ssl:default [Temporary failure in name resolution]

During handling of the above exception, another exception occurred:

Traceback (most recent call last):
  File "/home/nizomjon/PycharmProjects/Tiu_bot/.venv/lib/python3.9/site-packages/aiogram/dispatcher/dispatcher.py", line 381, in start_polling
    updates = await self.bot.get_updates(
  File "/home/nizomjon/PycharmProjects/Tiu_bot/.venv/lib/python3.9/site-packages/aiogram/bot/bot.py", line 110, in get_updates
    result = await self.request(api.Methods.GET_UPDATES, payload)
  File "/home/nizomjon/PycharmProjects/Tiu_bot/.venv/lib/python3.9/site-packages/aiogram/bot/base.py", line 236, in request
    return await api.make_request(await self.get_session(), self.server, self.__token, method, data, files,
  File "/home/nizomjon/PycharmProjects/Tiu_bot/.venv/lib/python3.9/site-packages/aiogram/bot/api.py", line 142, in make_request
    raise exceptions.NetworkError(f"aiohttp client throws an error: {e.__class__.__name__}: {e}")
aiogram.utils.exceptions.NetworkError: Aiohttp client throws an error: ClientConnectorError: Cannot connect to host api.telegram.org:443 ssl:default [Temporary failure in name resolution]
2025-10-21 00:59:04,444 - aiogram.dispatcher.dispatcher - ERROR - Cause exception while getting updates.
Traceback (most recent call last):
  File "/home/nizomjon/PycharmProjects/Tiu_bot/.venv/lib/python3.9/site-packages/aiohttp/connector.py", line 1155, in _create_direct_connection
    hosts = await asyncio.shield(host_resolved)
  File "/home/nizomjon/PycharmProjects/Tiu_bot/.venv/lib/python3.9/site-packages/aiohttp/connector.py", line 874, in _resolve_host
    addrs = await self._resolver.resolve(host, port, family=self._family)
  File "/home/nizomjon/PycharmProjects/Tiu_bot/.venv/lib/python3.9/site-packages/aiohttp/resolver.py", line 33, in resolve
    infos = await self._loop.getaddrinfo(
  File "/usr/local/lib/python3.9/asyncio/base_events.py", line 856, in getaddrinfo
    return await self.run_in_executor(
  File "/usr/local/lib/python3.9/concurrent/futures/thread.py", line 58, in run
    result = self.fn(*self.args, **self.kwargs)
  File "/usr/local/lib/python3.9/socket.py", line 954, in getaddrinfo
    for res in _socket.getaddrinfo(host, port, family, type, proto, flags):
socket.gaierror: [Errno -3] Temporary failure in name resolution

The above exception was the direct cause of the following exception:

Traceback (most recent call last):
  File "/home/nizomjon/PycharmProjects/Tiu_bot/.venv/lib/python3.9/site-packages/aiogram/bot/api.py", line 139, in make_request
    async with session.post(url, data=req, **kwargs) as response:
  File "/home/nizomjon/PycharmProjects/Tiu_bot/.venv/lib/python3.9/site-packages/aiohttp/client.py", line 1167, in __aenter__
    self._resp = await self._coro
  File "/home/nizomjon/PycharmProjects/Tiu_bot/.venv/lib/python3.9/site-packages/aiohttp/client.py", line 562, in _request
    conn = await self._connector.connect(
  File "/home/nizomjon/PycharmProjects/Tiu_bot/.venv/lib/python3.9/site-packages/aiohttp/connector.py", line 540, in connect
    proto = await self._create_connection(req, traces, timeout)
  File "/home/nizomjon/PycharmProjects/Tiu_bot/.venv/lib/python3.9/site-packages/aiohttp/connector.py", line 901, in _create_connection
    _, proto = await self._create_direct_connection(req, traces, timeout)
  File "/home/nizomjon/PycharmProjects/Tiu_bot/.venv/lib/python3.9/site-packages/aiohttp/connector.py", line 1169, in _create_direct_connection
    raise ClientConnectorError(req.connection_key, exc) from exc
aiohttp.client_exceptions.ClientConnectorError: Cannot connect to host api.telegram.org:443 ssl:default [Temporary failure in name resolution]

During handling of the above exception, another exception occurred:

Traceback (most recent call last):
  File "/home/nizomjon/PycharmProjects/Tiu_bot/.venv/lib/python3.9/site-packages/aiogram/dispatcher/dispatcher.py", line 381, in start_polling
    updates = await self.bot.get_updates(
  File "/home/nizomjon/PycharmProjects/Tiu_bot/.venv/lib/python3.9/site-packages/aiogram/bot/bot.py", line 110, in get_updates
    result = await self.request(api.Methods.GET_UPDATES, payload)
  File "/home/nizomjon/PycharmProjects/Tiu_bot/.venv/lib/python3.9/site-packages/aiogram/bot/base.py", line 236, in request
    return await api.make_request(await self.get_session(), self.server, self.__token, method, data, files,
  File "/home/nizomjon/PycharmProjects/Tiu_bot/.venv/lib/python3.9/site-packages/aiogram/bot/api.py", line 142, in make_request
    raise exceptions.NetworkError(f"aiohttp client throws an error: {e.__class__.__name__}: {e}")
aiogram.utils.exceptions.NetworkError: Aiohttp client throws an error: ClientConnectorError: Cannot connect to host api.telegram.org:443 ssl:default [Temporary failure in name resolution]
2025-10-21 00:59:09,451 - aiogram.dispatcher.dispatcher - ERROR - Cause exception while getting updates.
Traceback (most recent call last):
  File "/home/nizomjon/PycharmProjects/Tiu_bot/.venv/lib/python3.9/site-packages/aiohttp/connector.py", line 1155, in _create_direct_connection
    hosts = await asyncio.shield(host_resolved)
  File "/home/nizomjon/PycharmProjects/Tiu_bot/.venv/lib/python3.9/site-packages/aiohttp/connector.py", line 874, in _resolve_host
    addrs = await self._resolver.resolve(host, port, family=self._family)
  File "/home/nizomjon/PycharmProjects/Tiu_bot/.venv/lib/python3.9/site-packages/aiohttp/resolver.py", line 33, in resolve
    infos = await self._loop.getaddrinfo(
  File "/usr/local/lib/python3.9/asyncio/base_events.py", line 856, in getaddrinfo
    return await self.run_in_executor(
  File "/usr/local/lib/python3.9/concurrent/futures/thread.py", line 58, in run
    result = self.fn(*self.args, **self.kwargs)
  File "/usr/local/lib/python3.9/socket.py", line 954, in getaddrinfo
    for res in _socket.getaddrinfo(host, port, family, type, proto, flags):
socket.gaierror: [Errno -3] Temporary failure in name resolution

The above exception was the direct cause of the following exception:

Traceback (most recent call last):
  File "/home/nizomjon/PycharmProjects/Tiu_bot/.venv/lib/python3.9/site-packages/aiogram/bot/api.py", line 139, in make_request
    async with session.post(url, data=req, **kwargs) as response:
  File "/home/nizomjon/PycharmProjects/Tiu_bot/.venv/lib/python3.9/site-packages/aiohttp/client.py", line 1167, in __aenter__
    self._resp = await self._coro
  File "/home/nizomjon/PycharmProjects/Tiu_bot/.venv/lib/python3.9/site-packages/aiohttp/client.py", line 562, in _request
    conn = await self._connector.connect(
  File "/home/nizomjon/PycharmProjects/Tiu_bot/.venv/lib/python3.9/site-packages/aiohttp/connector.py", line 540, in connect
    proto = await self._create_connection(req, traces, timeout)
  File "/home/nizomjon/PycharmProjects/Tiu_bot/.venv/lib/python3.9/site-packages/aiohttp/connector.py", line 901, in _create_connection
    _, proto = await self._create_direct_connection(req, traces, timeout)
  File "/home/nizomjon/PycharmProjects/Tiu_bot/.venv/lib/python3.9/site-packages/aiohttp/connector.py", line 1169, in _create_direct_connection
    raise ClientConnectorError(req.connection_key, exc) from exc
aiohttp.client_exceptions.ClientConnectorError: Cannot connect to host api.telegram.org:443 ssl:default [Temporary failure in name resolution]

During handling of the above exception, another exception occurred:

Traceback (most recent call last):
  File "/home/nizomjon/PycharmProjects/Tiu_bot/.venv/lib/python3.9/site-packages/aiogram/dispatcher/dispatcher.py", line 381, in start_polling
    updates = await self.bot.get_updates(
  File "/home/nizomjon/PycharmProjects/Tiu_bot/.venv/lib/python3.9/site-packages/aiogram/bot/bot.py", line 110, in get_updates
    result = await self.request(api.Methods.GET_UPDATES, payload)
  File "/home/nizomjon/PycharmProjects/Tiu_bot/.venv/lib/python3.9/site-packages/aiogram/bot/base.py", line 236, in request
    return await api.make_request(await self.get_session(), self.server, self.__token, method, data, files,
  File "/home/nizomjon/PycharmProjects/Tiu_bot/.venv/lib/python3.9/site-packages/aiogram/bot/api.py", line 142, in make_request
    raise exceptions.NetworkError(f"aiohttp client throws an error: {e.__class__.__name__}: {e}")
aiogram.utils.exceptions.NetworkError: Aiohttp client throws an error: ClientConnectorError: Cannot connect to host api.telegram.org:443 ssl:default [Temporary failure in name resolution]
2025-10-21 00:59:14,456 - aiogram.dispatcher.dispatcher - ERROR - Cause exception while getting updates.
Traceback (most recent call last):
  File "/home/nizomjon/PycharmProjects/Tiu_bot/.venv/lib/python3.9/site-packages/aiohttp/connector.py", line 1155, in _create_direct_connection
    hosts = await asyncio.shield(host_resolved)
  File "/home/nizomjon/PycharmProjects/Tiu_bot/.venv/lib/python3.9/site-packages/aiohttp/connector.py", line 874, in _resolve_host
    addrs = await self._resolver.resolve(host, port, family=self._family)
  File "/home/nizomjon/PycharmProjects/Tiu_bot/.venv/lib/python3.9/site-packages/aiohttp/resolver.py", line 33, in resolve
    infos = await self._loop.getaddrinfo(
  File "/usr/local/lib/python3.9/asyncio/base_events.py", line 856, in getaddrinfo
    return await self.run_in_executor(
  File "/usr/local/lib/python3.9/concurrent/futures/thread.py", line 58, in run
    result = self.fn(*self.args, **self.kwargs)
  File "/usr/local/lib/python3.9/socket.py", line 954, in getaddrinfo
    for res in _socket.getaddrinfo(host, port, family, type, proto, flags):
socket.gaierror: [Errno -3] Temporary failure in name resolution

The above exception was the direct cause of the following exception:

Traceback (most recent call last):
  File "/home/nizomjon/PycharmProjects/Tiu_bot/.venv/lib/python3.9/site-packages/aiogram/bot/api.py", line 139, in make_request
    async with session.post(url, data=req, **kwargs) as response:
  File "/home/nizomjon/PycharmProjects/Tiu_bot/.venv/lib/python3.9/site-packages/aiohttp/client.py", line 1167, in __aenter__
    self._resp = await self._coro
  File "/home/nizomjon/PycharmProjects/Tiu_bot/.venv/lib/python3.9/site-packages/aiohttp/client.py", line 562, in _request
    conn = await self._connector.connect(
  File "/home/nizomjon/PycharmProjects/Tiu_bot/.venv/lib/python3.9/site-packages/aiohttp/connector.py", line 540, in connect
    proto = await self._create_connection(req, traces, timeout)
  File "/home/nizomjon/PycharmProjects/Tiu_bot/.venv/lib/python3.9/site-packages/aiohttp/connector.py", line 901, in _create_connection
    _, proto = await self._create_direct_connection(req, traces, timeout)
  File "/home/nizomjon/PycharmProjects/Tiu_bot/.venv/lib/python3.9/site-packages/aiohttp/connector.py", line 1169, in _create_direct_connection
    raise ClientConnectorError(req.connection_key, exc) from exc
aiohttp.client_exceptions.ClientConnectorError: Cannot connect to host api.telegram.org:443 ssl:default [Temporary failure in name resolution]

During handling of the above exception, another exception occurred:

Traceback (most recent call last):
  File "/home/nizomjon/PycharmProjects/Tiu_bot/.venv/lib/python3.9/site-packages/aiogram/dispatcher/dispatcher.py", line 381, in start_polling
    updates = await self.bot.get_updates(
  File "/home/nizomjon/PycharmProjects/Tiu_bot/.venv/lib/python3.9/site-packages/aiogram/bot/bot.py", line 110, in get_updates
    result = await self.request(api.Methods.GET_UPDATES, payload)
  File "/home/nizomjon/PycharmProjects/Tiu_bot/.venv/lib/python3.9/site-packages/aiogram/bot/base.py", line 236, in request
    return await api.make_request(await self.get_session(), self.server, self.__token, method, data, files,
  File "/home/nizomjon/PycharmProjects/Tiu_bot/.venv/lib/python3.9/site-packages/aiogram/bot/api.py", line 142, in make_request
    raise exceptions.NetworkError(f"aiohttp client throws an error: {e.__class__.__name__}: {e}")
aiogram.utils.exceptions.NetworkError: Aiohttp client throws an error: ClientConnectorError: Cannot connect to host api.telegram.org:443 ssl:default [Temporary failure in name resolution]
2025-10-21 00:59:19,460 - aiogram.dispatcher.dispatcher - ERROR - Cause exception while getting updates.
Traceback (most recent call last):
  File "/home/nizomjon/PycharmProjects/Tiu_bot/.venv/lib/python3.9/site-packages/aiohttp/connector.py", line 1155, in _create_direct_connection
    hosts = await asyncio.shield(host_resolved)
  File "/home/nizomjon/PycharmProjects/Tiu_bot/.venv/lib/python3.9/site-packages/aiohttp/connector.py", line 874, in _resolve_host
    addrs = await self._resolver.resolve(host, port, family=self._family)
  File "/home/nizomjon/PycharmProjects/Tiu_bot/.venv/lib/python3.9/site-packages/aiohttp/resolver.py", line 33, in resolve
    infos = await self._loop.getaddrinfo(
  File "/usr/local/lib/python3.9/asyncio/base_events.py", line 856, in getaddrinfo
    return await self.run_in_executor(
  File "/usr/local/lib/python3.9/concurrent/futures/thread.py", line 58, in run
    result = self.fn(*self.args, **self.kwargs)
  File "/usr/local/lib/python3.9/socket.py", line 954, in getaddrinfo
    for res in _socket.getaddrinfo(host, port, family, type, proto, flags):
socket.gaierror: [Errno -3] Temporary failure in name resolution

The above exception was the direct cause of the following exception:

Traceback (most recent call last):
  File "/home/nizomjon/PycharmProjects/Tiu_bot/.venv/lib/python3.9/site-packages/aiogram/bot/api.py", line 139, in make_request
    async with session.post(url, data=req, **kwargs) as response:
  File "/home/nizomjon/PycharmProjects/Tiu_bot/.venv/lib/python3.9/site-packages/aiohttp/client.py", line 1167, in __aenter__
    self._resp = await self._coro
  File "/home/nizomjon/PycharmProjects/Tiu_bot/.venv/lib/python3.9/site-packages/aiohttp/client.py", line 562, in _request
    conn = await self._connector.connect(
  File "/home/nizomjon/PycharmProjects/Tiu_bot/.venv/lib/python3.9/site-packages/aiohttp/connector.py", line 540, in connect
    proto = await self._create_connection(req, traces, timeout)
  File "/home/nizomjon/PycharmProjects/Tiu_bot/.venv/lib/python3.9/site-packages/aiohttp/connector.py", line 901, in _create_connection
    _, proto = await self._create_direct_connection(req, traces, timeout)
  File "/home/nizomjon/PycharmProjects/Tiu_bot/.venv/lib/python3.9/site-packages/aiohttp/connector.py", line 1169, in _create_direct_connection
    raise ClientConnectorError(req.connection_key, exc) from exc
aiohttp.client_exceptions.ClientConnectorError: Cannot connect to host api.telegram.org:443 ssl:default [Temporary failure in name resolution]

During handling of the above exception, another exception occurred:

Traceback (most recent call last):
  File "/home/nizomjon/PycharmProjects/Tiu_bot/.venv/lib/python3.9/site-packages/aiogram/dispatcher/dispatcher.py", line 381, in start_polling
    updates = await self.bot.get_updates(
  File "/home/nizomjon/PycharmProjects/Tiu_bot/.venv/lib/python3.9/site-packages/aiogram/bot/bot.py", line 110, in get_updates
    result = await self.request(api.Methods.GET_UPDATES, payload)
  File "/home/nizomjon/PycharmProjects/Tiu_bot/.venv/lib/python3.9/site-packages/aiogram/bot/base.py", line 236, in request
    return await api.make_request(await self.get_session(), self.server, self.__token, method, data, files,
  File "/home/nizomjon/PycharmProjects/Tiu_bot/.venv/lib/python3.9/site-packages/aiogram/bot/api.py", line 142, in make_request
    raise exceptions.NetworkError(f"aiohttp client throws an error: {e.__class__.__name__}: {e}")
aiogram.utils.exceptions.NetworkError: Aiohttp client throws an error: ClientConnectorError: Cannot connect to host api.telegram.org:443 ssl:default [Temporary failure in name resolution]
2025-10-21 00:59:24,464 - aiogram.dispatcher.dispatcher - ERROR - Cause exception while getting updates.
Traceback (most recent call last):
  File "/home/nizomjon/PycharmProjects/Tiu_bot/.venv/lib/python3.9/site-packages/aiohttp/connector.py", line 1155, in _create_direct_connection
    hosts = await asyncio.shield(host_resolved)
  File "/home/nizomjon/PycharmProjects/Tiu_bot/.venv/lib/python3.9/site-packages/aiohttp/connector.py", line 874, in _resolve_host
    addrs = await self._resolver.resolve(host, port, family=self._family)
  File "/home/nizomjon/PycharmProjects/Tiu_bot/.venv/lib/python3.9/site-packages/aiohttp/resolver.py", line 33, in resolve
    infos = await self._loop.getaddrinfo(
  File "/usr/local/lib/python3.9/asyncio/base_events.py", line 856, in getaddrinfo
    return await self.run_in_executor(
  File "/usr/local/lib/python3.9/concurrent/futures/thread.py", line 58, in run
    result = self.fn(*self.args, **self.kwargs)
  File "/usr/local/lib/python3.9/socket.py", line 954, in getaddrinfo
    for res in _socket.getaddrinfo(host, port, family, type, proto, flags):
socket.gaierror: [Errno -3] Temporary failure in name resolution

The above exception was the direct cause of the following exception:

Traceback (most recent call last):
  File "/home/nizomjon/PycharmProjects/Tiu_bot/.venv/lib/python3.9/site-packages/aiogram/bot/api.py", line 139, in make_request
    async with session.post(url, data=req, **kwargs) as response:
  File "/home/nizomjon/PycharmProjects/Tiu_bot/.venv/lib/python3.9/site-packages/aiohttp/client.py", line 1167, in __aenter__
    self._resp = await self._coro
  File "/home/nizomjon/PycharmProjects/Tiu_bot/.venv/lib/python3.9/site-packages/aiohttp/client.py", line 562, in _request
    conn = await self._connector.connect(
  File "/home/nizomjon/PycharmProjects/Tiu_bot/.venv/lib/python3.9/site-packages/aiohttp/connector.py", line 540, in connect
    proto = await self._create_connection(req, traces, timeout)
  File "/home/nizomjon/PycharmProjects/Tiu_bot/.venv/lib/python3.9/site-packages/aiohttp/connector.py", line 901, in _create_connection
    _, proto = await self._create_direct_connection(req, traces, timeout)
  File "/home/nizomjon/PycharmProjects/Tiu_bot/.venv/lib/python3.9/site-packages/aiohttp/connector.py", line 1169, in _create_direct_connection
    raise ClientConnectorError(req.connection_key, exc) from exc
aiohttp.client_exceptions.ClientConnectorError: Cannot connect to host api.telegram.org:443 ssl:default [Temporary failure in name resolution]

During handling of the above exception, another exception occurred:

Traceback (most recent call last):
  File "/home/nizomjon/PycharmProjects/Tiu_bot/.venv/lib/python3.9/site-packages/aiogram/dispatcher/dispatcher.py", line 381, in start_polling
    updates = await self.bot.get_updates(
  File "/home/nizomjon/PycharmProjects/Tiu_bot/.venv/lib/python3.9/site-packages/aiogram/bot/bot.py", line 110, in get_updates
    result = await self.request(api.Methods.GET_UPDATES, payload)
  File "/home/nizomjon/PycharmProjects/Tiu_bot/.venv/lib/python3.9/site-packages/aiogram/bot/base.py", line 236, in request
    return await api.make_request(await self.get_session(), self.server, self.__token, method, data, files,
  File "/home/nizomjon/PycharmProjects/Tiu_bot/.venv/lib/python3.9/site-packages/aiogram/bot/api.py", line 142, in make_request
    raise exceptions.NetworkError(f"aiohttp client throws an error: {e.__class__.__name__}: {e}")
aiogram.utils.exceptions.NetworkError: Aiohttp client throws an error: ClientConnectorError: Cannot connect to host api.telegram.org:443 ssl:default [Temporary failure in name resolution]
2025-10-21 00:59:29,473 - aiogram.dispatcher.dispatcher - ERROR - Cause exception while getting updates.
Traceback (most recent call last):
  File "/home/nizomjon/PycharmProjects/Tiu_bot/.venv/lib/python3.9/site-packages/aiohttp/connector.py", line 1155, in _create_direct_connection
    hosts = await asyncio.shield(host_resolved)
  File "/home/nizomjon/PycharmProjects/Tiu_bot/.venv/lib/python3.9/site-packages/aiohttp/connector.py", line 874, in _resolve_host
    addrs = await self._resolver.resolve(host, port, family=self._family)
  File "/home/nizomjon/PycharmProjects/Tiu_bot/.venv/lib/python3.9/site-packages/aiohttp/resolver.py", line 33, in resolve
    infos = await self._loop.getaddrinfo(
  File "/usr/local/lib/python3.9/asyncio/base_events.py", line 856, in getaddrinfo
    return await self.run_in_executor(
  File "/usr/local/lib/python3.9/concurrent/futures/thread.py", line 58, in run
    result = self.fn(*self.args, **self.kwargs)
  File "/usr/local/lib/python3.9/socket.py", line 954, in getaddrinfo
    for res in _socket.getaddrinfo(host, port, family, type, proto, flags):
socket.gaierror: [Errno -3] Temporary failure in name resolution

The above exception was the direct cause of the following exception:

Traceback (most recent call last):
  File "/home/nizomjon/PycharmProjects/Tiu_bot/.venv/lib/python3.9/site-packages/aiogram/bot/api.py", line 139, in make_request
    async with session.post(url, data=req, **kwargs) as response:
  File "/home/nizomjon/PycharmProjects/Tiu_bot/.venv/lib/python3.9/site-packages/aiohttp/client.py", line 1167, in __aenter__
    self._resp = await self._coro
  File "/home/nizomjon/PycharmProjects/Tiu_bot/.venv/lib/python3.9/site-packages/aiohttp/client.py", line 562, in _request
    conn = await self._connector.connect(
  File "/home/nizomjon/PycharmProjects/Tiu_bot/.venv/lib/python3.9/site-packages/aiohttp/connector.py", line 540, in connect
    proto = await self._create_connection(req, traces, timeout)
  File "/home/nizomjon/PycharmProjects/Tiu_bot/.venv/lib/python3.9/site-packages/aiohttp/connector.py", line 901, in _create_connection
    _, proto = await self._create_direct_connection(req, traces, timeout)
  File "/home/nizomjon/PycharmProjects/Tiu_bot/.venv/lib/python3.9/site-packages/aiohttp/connector.py", line 1169, in _create_direct_connection
    raise ClientConnectorError(req.connection_key, exc) from exc
aiohttp.client_exceptions.ClientConnectorError: Cannot connect to host api.telegram.org:443 ssl:default [Temporary failure in name resolution]

During handling of the above exception, another exception occurred:

Traceback (most recent call last):
  File "/home/nizomjon/PycharmProjects/Tiu_bot/.venv/lib/python3.9/site-packages/aiogram/dispatcher/dispatcher.py", line 381, in start_polling
    updates = await self.bot.get_updates(
  File "/home/nizomjon/PycharmProjects/Tiu_bot/.venv/lib/python3.9/site-packages/aiogram/bot/bot.py", line 110, in get_updates
    result = await self.request(api.Methods.GET_UPDATES, payload)
  File "/home/nizomjon/PycharmProjects/Tiu_bot/.venv/lib/python3.9/site-packages/aiogram/bot/base.py", line 236, in request
    return await api.make_request(await self.get_session(), self.server, self.__token, method, data, files,
  File "/home/nizomjon/PycharmProjects/Tiu_bot/.venv/lib/python3.9/site-packages/aiogram/bot/api.py", line 142, in make_request
    raise exceptions.NetworkError(f"aiohttp client throws an error: {e.__class__.__name__}: {e}")
aiogram.utils.exceptions.NetworkError: Aiohttp client throws an error: ClientConnectorError: Cannot connect to host api.telegram.org:443 ssl:default [Temporary failure in name resolution]
2025-10-21 00:59:34,480 - aiogram.dispatcher.dispatcher - ERROR - Cause exception while getting updates.
Traceback (most recent call last):
  File "/home/nizomjon/PycharmProjects/Tiu_bot/.venv/lib/python3.9/site-packages/aiohttp/connector.py", line 1155, in _create_direct_connection
    hosts = await asyncio.shield(host_resolved)
  File "/home/nizomjon/PycharmProjects/Tiu_bot/.venv/lib/python3.9/site-packages/aiohttp/connector.py", line 874, in _resolve_host
    addrs = await self._resolver.resolve(host, port, family=self._family)
  File "/home/nizomjon/PycharmProjects/Tiu_bot/.venv/lib/python3.9/site-packages/aiohttp/resolver.py", line 33, in resolve
    infos = await self._loop.getaddrinfo(
  File "/usr/local/lib/python3.9/asyncio/base_events.py", line 856, in getaddrinfo
    return await self.run_in_executor(
  File "/usr/local/lib/python3.9/concurrent/futures/thread.py", line 58, in run
    result = self.fn(*self.args, **self.kwargs)
  File "/usr/local/lib/python3.9/socket.py", line 954, in getaddrinfo
    for res in _socket.getaddrinfo(host, port, family, type, proto, flags):
socket.gaierror: [Errno -3] Temporary failure in name resolution

The above exception was the direct cause of the following exception:

Traceback (most recent call last):
  File "/home/nizomjon/PycharmProjects/Tiu_bot/.venv/lib/python3.9/site-packages/aiogram/bot/api.py", line 139, in make_request
    async with session.post(url, data=req, **kwargs) as response:
  File "/home/nizomjon/PycharmProjects/Tiu_bot/.venv/lib/python3.9/site-packages/aiohttp/client.py", line 1167, in __aenter__
    self._resp = await self._coro
  File "/home/nizomjon/PycharmProjects/Tiu_bot/.venv/lib/python3.9/site-packages/aiohttp/client.py", line 562, in _request
    conn = await self._connector.connect(
  File "/home/nizomjon/PycharmProjects/Tiu_bot/.venv/lib/python3.9/site-packages/aiohttp/connector.py", line 540, in connect
    proto = await self._create_connection(req, traces, timeout)
  File "/home/nizomjon/PycharmProjects/Tiu_bot/.venv/lib/python3.9/site-packages/aiohttp/connector.py", line 901, in _create_connection
    _, proto = await self._create_direct_connection(req, traces, timeout)
  File "/home/nizomjon/PycharmProjects/Tiu_bot/.venv/lib/python3.9/site-packages/aiohttp/connector.py", line 1169, in _create_direct_connection
    raise ClientConnectorError(req.connection_key, exc) from exc
aiohttp.client_exceptions.ClientConnectorError: Cannot connect to host api.telegram.org:443 ssl:default [Temporary failure in name resolution]

During handling of the above exception, another exception occurred:

Traceback (most recent call last):
  File "/home/nizomjon/PycharmProjects/Tiu_bot/.venv/lib/python3.9/site-packages/aiogram/dispatcher/dispatcher.py", line 381, in start_polling
    updates = await self.bot.get_updates(
  File "/home/nizomjon/PycharmProjects/Tiu_bot/.venv/lib/python3.9/site-packages/aiogram/bot/bot.py", line 110, in get_updates
    result = await self.request(api.Methods.GET_UPDATES, payload)
  File "/home/nizomjon/PycharmProjects/Tiu_bot/.venv/lib/python3.9/site-packages/aiogram/bot/base.py", line 236, in request
    return await api.make_request(await self.get_session(), self.server, self.__token, method, data, files,
  File "/home/nizomjon/PycharmProjects/Tiu_bot/.venv/lib/python3.9/site-packages/aiogram/bot/api.py", line 142, in make_request
    raise exceptions.NetworkError(f"aiohttp client throws an error: {e.__class__.__name__}: {e}")
aiogram.utils.exceptions.NetworkError: Aiohttp client throws an error: ClientConnectorError: Cannot connect to host api.telegram.org:443 ssl:default [Temporary failure in name resolution]
2025-10-21 01:24:34,279 - __main__ - INFO - ‚è∏ Bot is shutting down...
2025-10-21 01:24:34,281 - __main__ - INFO - ‚úÖ Bot stopped
2025-10-21 01:24:34,281 - aiogram.dispatcher.dispatcher - INFO - Stop polling...
2025-10-21 01:24:34,281 - aiogram - WARNING - Goodbye!
2025-10-21 01:24:36,631 - database.db - INFO - Database initialized successfully
2025-10-21 01:24:38,068 - aiogram - INFO - Bot: nizomjons_bot [@nizomjons_bot]
2025-10-21 01:24:39,095 - aiogram - WARNING - Updates were skipped successfully.
2025-10-21 01:24:39,095 - __main__ - INFO - üöÄ Bot is starting...
2025-10-21 01:24:39,503 - __main__ - INFO - Bot name: nizomjons_bot
2025-10-21 01:24:39,514 - __main__ - INFO - ‚úÖ All handlers registered successfully
2025-10-21 01:24:39,515 - __main__ - INFO - ‚úÖ Bot started successfully!
2025-10-21 01:24:39,515 - aiogram.dispatcher.dispatcher - INFO - Start polling.
2025-10-21 01:24:49,679 - database.db - INFO - Database initialized successfully
2025-10-21 01:36:46,757 - database.db - INFO - Database initialized successfully
2025-10-21 01:50:30,926 - __main__ - INFO - ‚è∏ Bot is shutting down...
2025-10-21 01:50:30,926 - __main__ - INFO - ‚úÖ Bot stopped
2025-10-21 01:50:30,926 - aiogram.dispatcher.dispatcher - INFO - Stop polling...
2025-10-21 01:50:30,927 - aiogram - WARNING - Goodbye!
2025-10-21 01:50:32,699 - database.db - INFO - Database initialized successfully
2025-10-21 01:50:35,002 - aiogram - INFO - Bot: nizomjons_bot [@nizomjons_bot]
2025-10-21 01:50:35,696 - aiogram - WARNING - Updates were skipped successfully.
2025-10-21 01:50:35,696 - __main__ - INFO - üöÄ Bot is starting...
2025-10-21 01:50:36,207 - __main__ - INFO - Bot name: nizomjons_bot
2025-10-21 01:50:36,221 - __main__ - INFO - ‚úÖ All handlers registered successfully
2025-10-21 01:50:36,221 - __main__ - INFO - ‚úÖ Bot started successfully!
2025-10-21 01:50:36,221 - aiogram.dispatcher.dispatcher - INFO - Start polling.
2025-10-21 01:58:33,610 - __main__ - INFO - ‚è∏ Bot is shutting down...
2025-10-21 01:58:33,611 - __main__ - INFO - ‚úÖ Bot stopped
2025-10-21 01:58:33,611 - aiogram.dispatcher.dispatcher - INFO - Stop polling...
2025-10-21 01:58:33,612 - aiogram - WARNING - Goodbye!
2025-10-21 01:58:35,619 - database.db - INFO - Database initialized successfully
2025-10-21 01:58:36,657 - aiogram - INFO - Bot: nizomjons_bot [@nizomjons_bot]
2025-10-21 01:58:37,886 - aiogram - WARNING - Updates were skipped successfully.
2025-10-21 01:58:37,886 - __main__ - INFO - üöÄ Bot is starting...
2025-10-21 01:58:38,095 - __main__ - INFO - Bot name: nizomjons_bot
2025-10-21 01:58:38,111 - __main__ - INFO - ‚úÖ All handlers registered successfully
2025-10-21 01:58:38,111 - __main__ - INFO - ‚úÖ Bot started successfully!
2025-10-21 01:58:38,111 - aiogram.dispatcher.dispatcher - INFO - Start polling.
2025-10-21 01:58:51,816 - database.db - ERROR - Error saving user: table users has 5 columns but 6 values were supplied
2025-10-21 01:59:28,060 - database.db - INFO - Database initialized successfully
2025-10-21 02:03:33,850 - __main__ - INFO - ‚è∏ Bot is shutting down...
2025-10-21 02:03:33,851 - __main__ - INFO - ‚úÖ Bot stopped
2025-10-21 02:03:33,851 - aiogram.dispatcher.dispatcher - INFO - Stop polling...
2025-10-21 02:03:33,851 - aiogram - WARNING - Goodbye!
2025-10-21 02:03:35,591 - database.db - INFO - Database initialized successfully
2025-10-21 02:03:36,891 - aiogram - INFO - Bot: nizomjons_bot [@nizomjons_bot]
2025-10-21 02:03:37,506 - aiogram - WARNING - Updates were skipped successfully.
2025-10-21 02:03:37,506 - __main__ - INFO - üöÄ Bot is starting...
2025-10-21 02:03:37,714 - __main__ - INFO - Bot name: nizomjons_bot
2025-10-21 02:03:37,726 - __main__ - INFO - ‚úÖ All handlers registered successfully
2025-10-21 02:03:37,726 - __main__ - INFO - ‚úÖ Bot started successfully!
2025-10-21 02:03:37,726 - aiogram.dispatcher.dispatcher - INFO - Start polling.
2025-10-21 02:03:42,432 - database.db - ERROR - Error saving user: table users has 5 columns but 6 values were supplied
2025-10-21 02:03:51,639 - database.db - INFO - Database initialized successfully
2025-10-21 02:09:32,390 - __main__ - INFO - ‚è∏ Bot is shutting down...
2025-10-21 02:09:32,390 - __main__ - INFO - ‚úÖ Bot stopped
2025-10-21 02:09:32,390 - aiogram.dispatcher.dispatcher - INFO - Stop polling...
2025-10-21 02:09:32,391 - aiogram - WARNING - Goodbye!
2025-10-21 02:09:34,112 - database.db - INFO - Database initialized successfully
2025-10-21 02:09:34,884 - aiogram - INFO - Bot: nizomjons_bot [@nizomjons_bot]
2025-10-21 02:09:35,611 - aiogram - WARNING - Updates were skipped successfully.
2025-10-21 02:09:35,612 - __main__ - INFO - üöÄ Bot is starting...
2025-10-21 02:09:35,907 - __main__ - INFO - Bot name: nizomjons_bot
2025-10-21 02:09:35,923 - __main__ - INFO - ‚úÖ All handlers registered successfully
2025-10-21 02:09:35,923 - __main__ - INFO - ‚úÖ Bot started successfully!
2025-10-21 02:09:35,924 - aiogram.dispatcher.dispatcher - INFO - Start polling.
2025-10-21 02:09:42,056 - database.db - ERROR - Error saving user: table users has 5 columns but 6 values were supplied
2025-10-21 02:09:46,367 - database.db - INFO - Database initialized successfully
2025-10-21 02:09:47,590 - database.db - INFO - Database initialized successfully
2025-10-21 02:10:00,897 - database.db - INFO - Database initialized successfully
2025-10-21 02:10:02,533 - database.db - INFO - Database initialized successfully
2025-10-21 02:13:20,378 - database.db - INFO - Database initialized successfully
2025-10-21 02:18:26,346 - database.db - INFO - Database initialized successfully
2025-10-22 00:24:13,043 - database.db - INFO - Database initialized successfully
2025-10-22 00:24:13,990 - aiogram - INFO - Bot: nizomjons_bot [@nizomjons_bot]
2025-10-22 00:24:14,399 - aiogram - WARNING - Updates were skipped successfully.
2025-10-22 00:24:14,399 - __main__ - INFO - üöÄ Bot is starting...
2025-10-22 00:24:14,602 - __main__ - INFO - Bot name: nizomjons_bot
2025-10-22 00:24:14,611 - __main__ - INFO - ‚úÖ All handlers registered successfully
2025-10-22 00:24:14,611 - __main__ - INFO - ‚úÖ Bot started successfully!
2025-10-22 00:24:14,611 - aiogram.dispatcher.dispatcher - INFO - Start polling.
2025-10-22 00:24:18,502 - database.db - ERROR - Error saving user: table users has 5 columns but 6 values were supplied
2025-10-22 00:24:33,557 - database.db - INFO - Database initialized successfully
2025-10-22 00:24:40,146 - database.db - INFO - Database initialized successfully
2025-10-22 00:24:41,446 - database.db - INFO - Database initialized successfully
2025-10-22 00:43:40,735 - aiogram.dispatcher.dispatcher - ERROR - Cause exception while getting updates.
Traceback (most recent call last):
  File "/home/nizomjon/PycharmProjects/Tiu_bot/.venv/lib/python3.9/site-packages/aiogram/dispatcher/dispatcher.py", line 381, in start_polling
    updates = await self.bot.get_updates(
  File "/home/nizomjon/PycharmProjects/Tiu_bot/.venv/lib/python3.9/site-packages/aiogram/bot/bot.py", line 110, in get_updates
    result = await self.request(api.Methods.GET_UPDATES, payload)
  File "/home/nizomjon/PycharmProjects/Tiu_bot/.venv/lib/python3.9/site-packages/aiogram/bot/base.py", line 236, in request
    return await api.make_request(await self.get_session(), self.server, self.__token, method, data, files,
  File "/home/nizomjon/PycharmProjects/Tiu_bot/.venv/lib/python3.9/site-packages/aiogram/bot/api.py", line 139, in make_request
    async with session.post(url, data=req, **kwargs) as response:
  File "/home/nizomjon/PycharmProjects/Tiu_bot/.venv/lib/python3.9/site-packages/aiohttp/client.py", line 1167, in __aenter__
    self._resp = await self._coro
  File "/home/nizomjon/PycharmProjects/Tiu_bot/.venv/lib/python3.9/site-packages/aiohttp/client.py", line 586, in _request
    await resp.start(conn)
  File "/home/nizomjon/PycharmProjects/Tiu_bot/.venv/lib/python3.9/site-packages/aiohttp/client_reqrep.py", line 920, in start
    self._continue = None
  File "/home/nizomjon/PycharmProjects/Tiu_bot/.venv/lib/python3.9/site-packages/aiohttp/helpers.py", line 725, in __exit__
    raise asyncio.TimeoutError from None
asyncio.exceptions.TimeoutError
2025-10-22 00:51:11,972 - database.db - INFO - Database initialized successfully
2025-10-22 00:51:15,257 - database.db - INFO - Database initialized successfully
2025-10-22 03:24:33,219 - database.db - INFO - Database initialized successfully
2025-10-22 03:25:14,174 - database.db - INFO - Database initialized successfully
2025-10-22 03:25:15,478 - database.db - INFO - Database initialized successfully
